Workbook

Sheet T
A1: English | B1: Albanian | C1: Arabic | D1: Armenian | E1: Azerbaijan | F1: Bulgarian | G1: Català | H1: Chinese (Simplified) | I1: Chinese (Traditional) | J1: Croatian | K1: Czech | L1: Danish | M1: Dutch | N1: Faroese | O1: French | P1: Georgian | Q1: German | R1: Greek | S1: Hebrew | T1: Hungarian | U1: Indonesia | V1: Icelandic | W1: Italian | X1: Korean | Y1: Lithuanian | Z1: Macedonian | AA1: Maltese | AB1: Norwegian | AC1: Persian | AD1: Polish | AE1: Portuguese | AF1: Romanian | AG1: Serbian | AH1: Slovak | AI1: Slovenian | AJ1: Spanish | AK1: Swedish | AL1: Thai | AM1: Turkish | AN1: Vietnamese | AO1: Ukrainian | AP1: Urdu
A2: 2026 World Cup Final Tournament Schedule | B2: Kupa Botërore 2026 | C2: جدول مباريات كأس العالم 2026 | D2: Աշխարհի 2026թ. առաջնություն | E2: 2026 - cu il Dünya Çempionatinin Final Mərhələsinin Cədvəli | F2: График на срещите - Световно първенство 2026 | G2: Calendari de la Fase Final de la Copa del Món de futbol 2026 | H2: 巴西2026年世界杯 | I2: 2026 世界盃賽程 | J2: Svjetsko prvenstvo 2026 raspored utakmica | K2: Mistrovství světa ve fotbale 2026 | L2: 2026 Verdensmesterskabs Oversigt | M2: Wereldkampioenschap 2026 Toernooischema | N2: 2026 Heimsmeistarakappingaryvirlit | O2: Coupe du Monde de la FIFA 2026 - Calendrier des matchs | P2: მსოფლიო ჩემპიონატი ფეხბურთში - სამხრეთ აფრიკა 2026 | Q2: Spielplan Weltmeisterschafts endrunde 2026 | R2: Πρόγραμμα Τελικών Παγκοσμίου Κυπέλλου 2026 | S2: 2026 גביע העולם טורניר הגמר תזמן | T2: 2026 Labdarúgó-világbajnokság döntő sorozata | U2: Jadwal Turnamen Final Piala Dunia 2026 | V2: HM 2026 lokakeppnin | W2: Calendario Coppa del mondo 2026 | X2: 2026 월드컵 최종 토너먼트 일정 | Y2: 2026 Pasaulio Futbolo Čempionato Tvarkaraštis | Z2: Светско првенство 2026 - Распоред на натпревари | AA2: Skeda tat-Tazza tad-Dinja 2026 | AB2: Verdensmesterskapet i fotball 2026 | AC2: جدول مسابقات فینال جام جهانی 2026 | AD2: 2026 Mistrzostwa Świata Terminarz Meczów | AE2: Calendário Fase Final Mundial 2026 | AF2: Programul Turneului Final FIFA World Cup 2026 | AG2: Svetsko prvenstvo u fudbalu 2026 - Raspored utakmica | AH2: Majstrovstvá sveta vo futbale 2026 | AI2: Svetovno prvenstvo 2026 razpored tekem | AJ2: Copa Mundial de Fútbol - Brasil 2026 | AK2: Schema för VM-slutspelet 2026 | AL2: ตารางการแข่งขันฟุตบอลโลก 2026 | AM2: 2026 Dünya Kupası Finalleri Turnuva Fikstürü | AN2: Lịch Thi Đấu Cúp Bóng Đá Thế Giới 2026 | AO2: Календар Чемпіонату Світу 2026 | AP2: ۲۰۱۰ فٹبال عالمی کپ ٹورنمنٹ کا خاکہ
A3: Group Stage | B3: Grupet | C3: الدور الأول | D3: Խմբային փուլ | E3: Qrup Mərhələsi | F3: Групова фаза | G3: Fase de grups | H3: 小组赛阶段 | I3: 分組賽 | J3: Prvi krug | K3: Základní skupiny | L3: Gruppespil | M3: Groepsfase | N3: Bólkaspæl | O3: Phase de groupes | P3: ჯგუფური ეტაპი | Q3: Gruppenphase | R3: Φάση Ομίλων | S3: שלב הבתים | T3: Csoportkörök | U3: Babak Kualifikasi | V3: Riðlakeppnin | W3: Fase a gironi | X3: 조별 리그 | Y3: Grupės Etapas | Z3: Фаза по групи | AA3: Fażi tal-Gruppi | AB3: Gruppespill | AC3: مرحله گروهی | AD3: Faza Grupowa | AE3: Fase de grupos | AF3: Faza Grupelor | AG3: Grupno takmičenje | AH3: Skupinová fáza | AI3: Skupinski del | AJ3: Fase de grupos | AK3: Gruppspel | AL3: รอบแรก | AM3: Grup Aşaması | AN3: Vòng Bảng | AO3: Груповий етап | AP3: گروپ بندی
A4: Round of 16 | B4: Rundi I 16 | C4: دور الستة عشر | D4: 1/8 Եզրափակիչ | E4: 16-da bir raund | F4: 1/8 - финали | G4: Vuitens de final | H4: 16强赛 | I4: 十六強 | J4: Drugi krug | K4: Osmifinále | L4: Runde af 16 | M4: Achtste finales | N4: Áttandapartsfinala | O4: Huitièmes de finale | P4: მერვედფინალი | Q4: Achtelfinale | R4: Φάση των 16 | S4: שמינית גמר | T4: Nyolcaddöntők | U4: Per Delapan Final | V4: 16 liða úrslit | W4: Ottavi di finale | X4: 16강전 | Y4: 16-tuko Raundas | Z4: 1/8 финале | AA4: L-Aħħar Sittax | AB4: 8-dels finale | AC4: یک هشتم نهائی | AD4: 1/8 Finału | AE4: Oitavos de Final | AF4: Optimi | AG4: Šesnaestina finala | AH4: Osemfinále | AI4: Osminafinala | AJ4: Octavos de final | AK4: Åttondelsfinal | AL4: รอบสอง | AM4: Son 16 | AN4: Vòng 1/16 | AO4: 1/8 фіналу | AP4: سولھواں دور
A5: Quarterfinals | B5: Qerekfinalja | C5: دور الربع نهائي | D5: 1/4 Եզրափակիչ | E5: Dörddə bir Final | F5: 1/4 - финали | G5: Quarts de final | H5: 8强赛 | I5: 八強 | J5: Četvrtfinale | K5: Čtvrtfinále | L5: Kvartfinale | M5: Kwartfinales | N5: Fjórðingsfinala | O5: Quart de Finale | P5: მეოთხედფინალი | Q5: Viertelfinale | R5: Προημιτελικοί | S5: רבע גמר | T5: Negyeddöntők | U5: Perempat Final | V5: 8 liða úrslit | W5: Quarti di finale | X5: 8강전 | Y5: Ketvirtfinaliai | Z5: 1/4 финале | AA5: Kwarti-Finali | AB5: Kvartfinale | AC5: یک چهارم نهائی | AD5: Ćwierćfinały | AE5: Quartos de Final | AF5: Sferturi de finala | AG5: Četvrtfinale | AH5: Štvrťfinále | AI5: Četrtfinale | AJ5: Cuartos de Final | AK5: Kvartsfinal | AL5: รอบก่อนรองชนะเลิศ | AM5: Çeyrek Final | AN5: Tứ kết | AO5: Чвертьфінал | AP5: کواٹر فائنل
A6: Semi-Finals | B6: Gjysmëfinalja | C6: دور النصف نهائي | D6: Կիսաեզրափակիչ | E6: Yarım Final | F6: 1/2 - финали | G6: Semifinals | H6: 半决赛 | I6: 準決賽 | J6: Polufinale | K6: Semifinále | L6: Semifinale | M6: Halve finales | N6: Hálvfinala | O6: Demi-Finale | P6: ნახევარფინალი | Q6: Halbfinale | R6: Ημιτελικοί | S6: חצי גמר | T6: Elődöntők | U6: Semi Final | V6: Undanúrslit | W6: Semifinali | X6: 준결승전 | Y6: Pusfinaliai | Z6: 1/2 финале | AA6: Semi-Finali | AB6: Semifinale | AC6: نیمه نهائی | AD6: Półfinały | AE6: Semi-final | AF6: Semifinale | AG6: Polufinale | AH6: Semifinále | AI6: Polfinale | AJ6: Semifinales | AK6: Semifinal | AL6: รอบรองชนะเลิศ | AM6: Yarı Final | AN6: Bán kết | AO6: Півфінал | AP6: سیمی فائنل
A7: Third-Place Play-Off | B7: Takimi për vendin e tretë | C7: تحديد المركزين الثالث والرابع | D7: 3-րդ տեղի համար եզրափակիչ | E7: Üçüncü Yer Uğrunda | F7: Мач за трето място | G7: 3r i 4t lloc | H7: 季军赛 | I7: 季軍賽 | J7: Za treće mjesto | K7: Zápas o 3.místo | L7: Tredjeplads Kamp | M7: Derde en vierde plaats | N7: Dystur um 3. pláss | O7: Match pour la troisième place | P7: მესამე ადგილი | Q7: Spiel um den dritten Platz | R7: Μικρός Τελικός | S7: מקום 3-4 | T7: Bronzmeccs | U7: Perebutan Tempat Ketiga | V7: Leikur um 3.sæti | W7: Finale 3°- 4° posto | X7: 3,4위전 | Y7: Rungtynės dėl Trečios Vietos | Z7: Натпревар за трето место | AA7: Final għat-Tielet u r-Raba' Post | AB7: Bronsefinale | AC7: رده بندی | AD7: Mecz o trzecie miejsce | AE7: 3º/4º lugar | AF7: Finala mica | AG7: Za treće mjesto | AH7: Zápas o 3. miesto | AI7: Za tretje mesto | AJ7: Tercer puesto | AK7: Match om tredje pris | AL7: รอบชิงที่ 3 | AM7: Üçüncülük Maçı | AN7: Tranh hạng 3 | AO7: Матч за третє місце | AP7: تیسرے مقام کے لئے کھیل
A8: Final | B8: Finalja | C8: المباراة النهائية | D8: Եզրափակիչ | E8: Final | F8: Финал | G8: Final | H8: 总决赛 | I8: 總決賽 | J8: Finale | K8: Finále | L8: Finale | M8: Finale | N8: Finala | O8: Finale | P8: ფინალი | Q8: Finale | R8: Τελικός | S8: גמר | T8: Döntő | U8: Final | V8: Úrslit | W8: Finale | X8: 결승전 | Y8: Finalas | Z8: Финале | AA8: Finali | AB8: Finale | AC8: فینال | AD8: Finał | AE8: Final | AF8: FINALA | AG8: Finale | AH8: Finále | AI8: Finale | AJ8: Final | AK8: Final | AL8: รอบชิงชนะเลิศ | AM8: Final | AN8: Chung Kết | AO8: Фінал | AP8: فائنل
A9: Group | B9: Grupi | C9: المجموعة | D9: Խումբ | E9: Qrup | F9: Група | G9: Grup | H9: 小组 | I9: 小組 | J9: Grupa | K9: Skupina | L9: Gruppe | M9: Groep | N9: Bólkur | O9: Groupe | P9: ჯგუფი | Q9: Gruppe | R9: Όμιλος | S9: בית | T9: Csoport | U9: Kelompok | V9: Riðill | W9: Gruppo | X9: 그룹 | Y9: Grupė | Z9: Група | AA9: Grupp | AB9: Gruppe | AC9: گروه | AD9: Grupa | AE9: Grupo | AF9: Grupa | AG9: Grupa | AH9: Skupina | AI9: Skupina | AJ9: Grupo | AK9: Grupp | AL9: สาย | AM9: Grup | AN9: Bảng | AO9: Група | AP9: گروپ بندی
A10: PL | B10: L | C10: لعب | D10: Խ | E10: O | F10: М | G10: J | H10: 场次 | I10: 賽 | J10: PL | K10: Z | L10: SP | M10: WG | N10: SP | O10: J | P10: თ | Q10: SP | R10: ΑΓ | S10: משחקים | T10: M | U10: Main | V10: L | W10: G | X10: 경기 | Y10: Žst | Z10: О | AA10: L | AB10: S | AC10: بازی | AD10: M | AE10: J | AF10: J | AG10: UT | AH10: Z | AI10: PL | AJ10: J | AK10: Sp | AL10: แข่ง | AM10: O | AN10: Trận | AO10: І | AP10: کھیلے گئے مقابلے
A11: W | B11: F | C11: فاز | D11: Հ | E11: Q | F11: П | G11: G | H11: 胜 | I11: 勝 | J11: W | K11: V | L11: V | M11: W | N11: V | O11: V | P11: მოგ | Q11: S | R11: Ν | S11: נצחונות | T11: GY | U11: Menang | V11: U | W11: V | X11: 승 | Y11: L | Z11: П | AA11: R | AB11: V | AC11: برد | AD11: Z | AE11: V | AF11: V | AG11: P | AH11: V | AI11: W | AJ11: G | AK11: V | AL11: ชนะ | AM11: G | AN11: T | AO11: В | AP11: جیت
A12: DRAW | B12: BAR | C12: تعادل | D12: Ո | E12: H | F12: Р | G12: E | H12: 平 | I12: 和 | J12: DRAW | K12: R | L12: Uafgjort | M12: G | N12: J | O12: DRAW | P12: ფრე | Q12: DRAW | R12: Ι | S12: תיקו | T12: D | U12: Seri | V12: Jafnt | W12: P | X12: 무 | Y12: Lyg | Z12: Н | AA12: I | AB12: T | AC12: مساوی | AD12: R | AE12: E | AF12: E | AG12: NER. | AH12: R | AI12: DRAW | AJ12: DRAW | AK12: O | AL12: เสมอ | AM12: B | AN12: H | AO12: Н | AP12: برابر
... A157: en | B157: sq | C157: ar | D157: hy | E157: az | F157: bg | G157: ca | H157: zh-CN | I157: zh-TW | J157: hr | K157: cs | L157: da | M157: nl | N157: fr | O157: fr | P157: ka | Q157: de | R157: el | S157: iw | T157: hu | U157: id | V157: is | W157: it | X157: ko | Y157: lt | Z157: mk | AA157: mt | AB157: no | AC157: fa | AD157: pl | AE157: pt | AF157: ro | AG157: sr | AH157: sk | AI157: sl | AJ157: es | AK157: sv | AL157: th | AM157: tr | AN157: vi | AO157: uk | AP157: ur

Sheet Settings
B2: Settings | F2: Group Round Sorting
B4: Language | C4: English
F5: Step #1 | G5: Points
B6: Summer Time | C6: Yes | F6: Step #2 | G6: Concerned teams (Pnt, GF-GA, GF)
F7: Step #3 | G7: Goal Difference | AA7: {=IF(OR(E7=settings!i15my_team,H7=my_team),1,0)} -> #NAME?
B8: GTM-Time | C8: GMT + 1:00 | F8: Step #4 | G8: Goals Scored
F9: Step #5 | G9: FIFA Rank
B10: Minutes | C10: +0 min
B12: Favorite Team
B14: Group Matches | C14: No
F15: Language ID | G15: =IF(ISERROR(MATCH(C4,lang_list,0)),1,MATCH(C4,lang_list,0)) -> 1 | I15: =IFERROR(VLOOKUP(C12,T,lang,FALSE()),"")
F16: GMT Delta | G16: =TIME(VLOOKUP(C8,F18:G42,2,FALSE()),VLOOKUP(C10,F44:G47,2,FALSE()),0)+IF(C6="Yes",TIME(1,0,0),0) -> 0.54166667
I17: Algeria
C18: FIFA Rank | F18: GMT - 11:00 | G18: 0 | I18: Argentina
B19: =VLOOKUP("France",T,lang,FALSE()) -> France | C19: 1877.32 | F19: GMT - 10:00 | G19: 1 | I19: Australia
B20: =VLOOKUP("Spain",T,lang,FALSE()) -> Spain | C20: 1876.4 | F20: GMT - 9:00 | G20: 2 | I20: Austria
B21: =VLOOKUP("Argentina",T,lang,FALSE()) -> Argentina | C21: 1874.82 | F21: GMT - 8:00 | G21: 3 | I21: Belgium
B22: =VLOOKUP("England",T,lang,FALSE()) -> England | C22: 1825.97 | F22: GMT - 7:00 | G22: 4 | I22: Bosnia and Herzegovina
B23: =VLOOKUP("Portugal",T,lang,FALSE()) -> Portugal | C23: 1763.83 | F23: GMT - 6:00 | G23: 5 | I23: Brazil
B24: =VLOOKUP("Brazil",T,lang,FALSE()) -> Brazil | C24: 1761.16 | F24: GMT - 5:00 | G24: 6 | I24: Canada
B25: =VLOOKUP("Netherlands",T,lang,FALSE()) -> Netherlands | C25: 1757.87 | F25: GMT - 4:00 | G25: 7 | I25: Cape Verde
B26: =VLOOKUP("Morocco",T,lang,FALSE()) -> Morocco | C26: 1755.87 | F26: GMT - 3:00 | G26: 8 | I26: Colombia
B27: =VLOOKUP("Belgium",T,lang,FALSE()) -> Belgium | C27: 1734.71 | F27: GMT - 2:00 | G27: 9 | I27: Croatia
B28: =VLOOKUP("Germany",T,lang,FALSE()) -> Germany | C28: 1730.37 | F28: GMT - 1:00 | G28: 10 | I28: Curaçao
B29: =VLOOKUP("Croatia",T,lang,FALSE()) -> Croatia | C29: 1717.07 | F29: GMT | G29: 11 | I29: Czech Republic
B30: =VLOOKUP("Colombia",T,lang,FALSE()) -> Colombia | C30: 1693.09 | F30: GMT + 1:00 | G30: 12 | I30: DR Congo
B31: =VLOOKUP("Senegal",T,lang,FALSE()) -> Senegal | C31: 1688.99 | F31: GMT + 2:00 | G31: 13 | I31: Ecuador
B32: =VLOOKUP("Mexico",T,lang,FALSE()) -> Mexico | C32: 1681.03 | F32: GMT + 3:00 | G32: 14 | I32: Egypt
B33: =VLOOKUP("United States",T,lang,FALSE()) -> United States | C33: 1673.13 | F33: GMT + 4:00 | G33: 15 | I33: England
B34: =VLOOKUP("Uruguay",T,lang,FALSE()) -> Uruguay | C34: 1673.07 | F34: GMT + 5:00 | G34: 16 | I34: France
B35: =VLOOKUP("Japan",T,lang,FALSE()) -> Japan | C35: 1660.43 | F35: GMT + 6:00 | G35: 17 | I35: Germany
B36: =VLOOKUP("Switzerland",T,lang,FALSE()) -> Switzerland | C36: 1649.4 | F36: GMT + 7:00 | G36: 18 | I36: Ghana
B37: =VLOOKUP("Iran",T,lang,FALSE()) -> Iran | C37: 1615.3 | F37: GMT + 8:00 | G37: 19 | I37: Haiti
B38: =VLOOKUP("Turkey",T,lang,FALSE()) -> Turkey | C38: 1599.04 | F38: GMT + 9:00 | G38: 20 | I38: Iran
B39: =VLOOKUP("Ecuador",T,lang,FALSE()) -> Ecuador | C39: 1594.78 | F39: GMT + 10:00 | G39: 21 | I39: Iraq
B40: =VLOOKUP("Austria",T,lang,FALSE()) -> Austria | C40: 1593.45 | F40: GMT + 11:00 | G40: 22 | I40: Ivory Coast
B41: =VLOOKUP("Korea Republic",T,lang,FALSE()) -> Korea Republic | C41: 1588.66 | F41: GMT + 12:00 | G41: 23 | I41: Japan
B42: =VLOOKUP("Australia",T,lang,FALSE()) -> Australia | C42: 1580.67 | F42: GMT + 13:00 | G42: 24 | I42: Jordan
B43: =VLOOKUP("Algeria",T,lang,FALSE()) -> Algeria | C43: 1564.26 | I43: Korea Republic
B44: =VLOOKUP("Egypt",T,lang,FALSE()) -> Egypt | C44: 1563.24 | F44: +0 min | G44: 0 | I44: Mexico
...

Sheet 2026 World Cup
A1: {=INDEX(T,2,lang)} -> 2026 World Cup Final Tournament Schedule
O3: ="Language: " & Settings!C4 -> Language: English
A5: {=INDEX(T,3,lang)} -> Group Stage | J5: Home Page: www.excely.com
R6: Date + Time + GMT | V6: GF | W6: GA | Y6: GF | Z6: GA | AA6: =IF(Settings!C14="Yes",INT(MATCH(my_team,$AE$8:$AE$78,0)/6),-1) -> -1 | AD6: Place | AE6: Team | AF6: W | AG6: D | AH6: L | AI6: GF | AJ6: GA | AL6: F-A | AM6: F-A (norm) | AN6: Pnt | AO6: R1 | AP6: R2 | AQ6: FIFA | AR6: Rank | AT6: W | AU6: D | AV6: GF | AW6: GA | AX6: F-A | AY6: F-A (norm) | AZ6: Rank | BA6: R (norm) | BB6: W | BC6: D | BD6: GF | BE6: GA | BF6: F-A | BG6: F-A (norm) | BH6: Rank | BI6: R (norm) | BK6: Round of 32 | BR6: {=INDEX(T,4,lang)} -> Round of 16 | BY6: {=INDEX(T,5,lang)} -> Quarterfinals | CF6: {=INDEX(T,6,lang)} -> Semi-Finals
A7: 1 | B7: {=INDEX(T,18+INT(MOD(R7-1,7)),lang)} -> Thu | C7: {=INDEX(T,24+MONTH(R7),lang) & " " & DAY(R7) & ", " & YEAR(R7)} -> Jun 11, 2026 | D7: =TIME(HOUR(R7),MINUTE(R7),0) -> 0.875 | E7: =AE8 -> Mexico | F7: 2 | G7: 0 | H7: =AE9 -> South Africa | R7: =DATE(2026,6,11)+TIME(8,0,0)+gmt_delta -> 46184.875 | S7: =IF(OR(F7="",G7=""),"",IF(F7>G7,E7&"_win",IF(F7<G7,E7&"_lose",E7&"_draw"))) -> Mexico_win | T7: =IF(S7="","",IF(F7<G7,H7&"_win",IF(F7>G7,H7&"_lose",H7&"_draw"))) -> South Africa_lose | U7: =IF(S7="",0,IF(VLOOKUP(E7,$AE$8:$AN$77,10,FALSE())=VLOOKUP(H7,$AE$8:$AN$77,10,FALSE()),1,0)) -> 0 | V7: =U7*F7 -> 0 | W7: =U7*G7 -> 0 | X7: =IF(S7="",0,IF(VLOOKUP(E7,$AE$8:$AO$77,11,FALSE())=VLOOKUP(H7,$AE$8:$AO$77,11,FALSE()),1,0)) -> 0 | Y7: =X7*F7 -> 0 | Z7: =X7*G7 -> 0 | AA7: =IF(OR(E7=my_team,H7=my_team),1,IF(INT(MATCH(E7,$AE$8:$AE$78,0)/6)=$AA$6,1,0)) -> 0 | AB7: =IF(OR(F7="",G7=""),"",IF(F7>G7,1,IF(F7<G7,-1,0))) -> 1
A8: 2 | B8: {=INDEX(T,18+INT(MOD(R8-1,7)),lang)} -> Fri | C8: {=INDEX(T,24+MONTH(R8),lang) & " " & DAY(R8) & ", " & YEAR(R8)} -> Jun 12, 2026 | D8: =TIME(HOUR(R8),MINUTE(R8),0) -> 0.16666667 | E8: =AE10 -> Korea Republic | F8: 2 | G8: 1 | H8: =AE11 -> Czech Republic | J8: {=INDEX(T,9,lang) & " " & "A"} -> Group A | K8: {=INDEX(T,10,lang)} -> PL | L8: {=INDEX(T,11,lang)} -> W | M8: {=INDEX(T,12,lang)} -> DRAW | N8: {=INDEX(T,13,lang)} -> L | O8: {=INDEX(T,14,lang)} -> GF - GA | P8: {=INDEX(T,15,lang)} -> PNT | R8: =DATE(2026,6,11)+TIME(15,0,0)+gmt_delta -> 46185.167 | S8: =IF(OR(F8="",G8=""),"",IF(F8>G8,E8&"_win",IF(F8<G8,E8&"_lose",E8&"_draw"))) -> Korea Republic_win | T8: =IF(S8="","",IF(F8<G8,H8&"_win",IF(F8>G8,H8&"_lose",H8&"_draw"))) -> Czech Republic_lose | U8: =IF(S8="",0,IF(VLOOKUP(E8,$AE$8:$AN$77,10,FALSE())=VLOOKUP(H8,$AE$8:$AN$77,10,FALSE()),1,0)) -> 0 | V8: =U8*F8 -> 0 | W8: =U8*G8 -> 0 | X8: =IF(S8="",0,IF(VLOOKUP(E8,$AE$8:$AO$77,11,FALSE())=VLOOKUP(H8,$AE$8:$AO$77,11,FALSE()),1,0)) -> 0 | Y8: =X8*F8 -> 0 | Z8: =X8*G8 -> 0 | AA8: =IF(OR(E8=my_team,H8=my_team),1,IF(INT(MATCH(E8,$AE$8:$AE$78,0)/6)=$AA$6,1,0)) -> 0 | AB8: =IF(OR(F8="",G8=""),"",IF(F8>G8,1,IF(F8<G8,-1,0))) -> 1 | AD8: =COUNTIF(AR8:AR11,CONCATENATE(">=",AR8)) -> 1 | AE8: =VLOOKUP("Mexico",T,lang,FALSE()) -> Mexico | AF8: =COUNTIF($S$7:$T$78,"=" & AE8 & "_win") -> 3 | AG8: =COUNTIF($S$7:$T$78,"=" & AE8 & "_draw") -> 0 | AH8: =COUNTIF($S$7:$T$78,"=" & AE8 & "_lose") -> 0 | AI8: =SUMIF($E$7:$E$78,$AE8,$F$7:$F$78) + SUMIF($H$7:$H$78,$AE8,$G$7:$G$78) -> 6 | AJ8: =SUMIF($E$7:$E$78,$AE8,$G$7:$G$78) + SUMIF($H$7:$H$78,$AE8,$F$7:$F$78) -> 2 | AL8: =AI8-AJ8 -> 4 | AM8: =AL8-AL12 -> 8 | AN8: =AF8*3+AG8 -> 9 | AO8: =AN8/AN12*10+BA8 -> 9 | AP8: =AO8*10000000+BI8*100+AM8/AM12*10+AI8/AI12*1++IF(AQ8=0,ROW(),AQ8)/2000000 -> 90000010 | AQ8: =VLOOKUP(AE8,db_fifarank,2,FALSE()) -> 1681.03 | AR8: =AP8/AP12 -> 0.99999999 | AS8: =IF(SUM(AF8:AH11)=12,J9,"1A") -> Mexico | AT8: {=SUMPRODUCT(($S$7:$S$78=AE8&"_win")*($U$7:$U$78))+SUMPRODUCT(($T$7:$T$78=AE8&"_win")*($U$7:$U$78))} -> 0 | AU8: {=SUMPRODUCT(($S$7:$S$78=AE8&"_draw")*($U$7:$U$78))+SUMPRODUCT(($T$7:$T$78=AE8&"_draw")*($U$7:$U$78))} -> 0 | AV8: {=SUMPRODUCT(($E$7:$E$78=AE8)*($U$7:$U$78)*($F$7:$F$78))+SUMPRODUCT(($H$7:$H$78=AE8)*($U$7:$U$78)*($G$7:$G$78))} -> 0 | AW8: {=SUMPRODUCT(($E$7:$E$78=AE8)*($U$7:$U$78)*($G$7:$G$78))+SUMPRODUCT(($H$7:$H$78=AE8)*($U$7:$U$78)*($F$7:$F$78))} -> 0 | AX8: =AV8-AW8 -> 0 | AY8: =AX8-MIN(AX8:AX11) -> 0 | AZ8: =AT8/AT12*1000+AU8/AU12*100+AY8/AY12*10+AV8/AV12 -> 0 | BA8: =AZ8/AZ12 -> 0 | BB8: {=SUMPRODUCT(($S$7:$S$78=AE8&"_win")*($X$7:$X$78))+SUMPRODUCT(($T$7:$T$78=AE8&"_win")*($X$7:$X$78))} -> 0 | BC8: {=SUMPRODUCT(($S$7:$S$78=AE8&"_draw")*($X$7:$X$78))+SUMPRODUCT(($T$7:$T$78=AE8&"_draw")*($X$7:$X$78))} -> 0 | BD8: {=SUMPRODUCT(($E$7:$E$78=AE8)*($X$7:$X$78)*($F$7:$F$78))+SUMPRODUCT(($H$7:$H$78=AE8)*($X$7:$X$78)*($G$7:$G$78))} -> 0 | BE8: {=SUMPRODUCT(($E$7:$E$78=AE8)*($X$7:$X$78)*($G$7:$G$78))+SUMPRODUCT(($H$7:$H$78=AE8)*($X$7:$X$78)*($F$7:$F$78))} -> 0 | BF8: =BD8-BE8 -> 0 | BG8: =BF8-MIN(BF8:BF11) -> 0 | BH8: =BB8/BB12*1000+BC8/BC12*100+BG8/BG12*10+BD8/BD12 -> 0 | BI8: =BH8/BH12 -> 0
A9: 3 | B9: {=INDEX(T,18+INT(MOD(R9-1,7)),lang)} -> Fri | C9: {=INDEX(T,24+MONTH(R9),lang) & " " & DAY(R9) & ", " & YEAR(R9)} -> Jun 12, 2026 | D9: =TIME(HOUR(R9),MINUTE(R9),0) -> 0.875 | E9: =AE14 -> Canada | F9: 2 | G9: 1 | H9: =AE15 -> Bosnia and Herzegovina | J9: =VLOOKUP(1,AD8:AN11,2,FALSE()) -> Mexico | K9: =L9+M9+N9 -> 3 | L9: =VLOOKUP(1,AD8:AN11,3,FALSE()) -> 3 | M9: =VLOOKUP(1,AD8:AN11,4,FALSE()) -> 0 | N9: =VLOOKUP(1,AD8:AN11,5,FALSE()) -> 0 | O9: =VLOOKUP(1,AD8:AN11,6,FALSE()) & " - " & VLOOKUP(1,AD8:AN11,7,FALSE()) -> 6 - 2 | P9: =L9*3+M9 -> 9 | R9: =DATE(2026,6,12)+TIME(8,0,0)+gmt_delta -> 46185.875 | S9: =IF(OR(F9="",G9=""),"",IF(F9>G9,E9&"_win",IF(F9<G9,E9&"_lose",E9&"_draw"))) -> Canada_win | T9: =IF(S9="","",IF(F9<G9,H9&"_win",IF(F9>G9,H9&"_lose",H9&"_draw"))) -> Bosnia and Herzegovina_lose | U9: =IF(S9="",0,IF(VLOOKUP(E9,$AE$8:$AN$77,10,FALSE())=VLOOKUP(H9,$AE$8:$AN$77,10,FALSE()),1,0)) -> 0 | V9: =U9*F9 -> 0 | W9: =U9*G9 -> 0 | X9: =IF(S9="",0,IF(VLOOKUP(E9,$AE$8:$AO$77,11,FALSE())=VLOOKUP(H9,$AE$8:$AO$77,11,FALSE()),1,0)) -> 0 | Y9: =X9*F9 -> 0 | Z9: =X9*G9 -> 0 | AA9: =IF(OR(E9=my_team,H9=my_team),1,IF(INT(MATCH(E9,$AE$8:$AE$78,0)/6)=$AA$6,1,0)) -> 0 | AB9: =IF(OR(F9="",G9=""),"",IF(F9>G9,1,IF(F9<G9,-1,0))) -> 1 | AD9: =COUNTIF(AR8:AR11,CONCATENATE(">=",AR9)) -> 4 | AE9: =VLOOKUP("South Africa",T,lang,FALSE()) -> South Africa | AF9: =COUNTIF($S$7:$T$78,"=" & AE9 & "_win") -> 0 | AG9: =COUNTIF($S$7:$T$78,"=" & AE9 & "_draw") -> 0 | AH9: =COUNTIF($S$7:$T$78,"=" & AE9 & "_lose") -> 3 | AI9: =SUMIF($E$7:$E$78,$AE9,$F$7:$F$78) + SUMIF($H$7:$H$78,$AE9,$G$7:$G$78) -> 1 | AJ9: =SUMIF($E$7:$E$78,$AE9,$G$7:$G$78) + SUMIF($H$7:$H$78,$AE9,$F$7:$F$78) -> 5 | AL9: =AI9-AJ9 -> -4 | AM9: =AL9-AL12 -> 0 | AN9: =AF9*3+AG9 -> 0 | AO9: =AN9/AN12*10+BA9 -> 0 | AP9: =AO9*10000000+BI9*100+AM9/AM12*10+AI9/AI12*1++IF(AQ9=0,ROW(),AQ9)/2000000 -> 0.14357201 | AQ9: =VLOOKUP(AE9,db_fifarank,2,FALSE()) -> 1429.73 | AR9: =AP9/AP12 -> 1.5952443e-09 | AS9: =IF(SUM(AF8:AH11)=12,J10,"2A") -> Korea Republic | AT9: {=SUMPRODUCT(($S$7:$S$78=AE9&"_win")*($U$7:$U$78))+SUMPRODUCT(($T$7:$T$78=AE9&"_win")*($U$7:$U$78))} -> 0 | AU9: {=SUMPRODUCT(($S$7:$S$78=AE9&"_draw")*($U$7:$U$78))+SUMPRODUCT(($T$7:$T$78=AE9&"_draw")*($U$7:$U$78))} -> 0 | AV9: {=SUMPRODUCT(($E$7:$E$78=AE9)*($U$7:$U$78)*($F$7:$F$78))+SUMPRODUCT(($H$7:$H$78=AE9)*($U$7:$U$78)*($G$7:$G$78))} -> 0 | AW9: {=SUMPRODUCT(($E$7:$E$78=AE9)*($U$7:$U$78)*($G$7:$G$78))+SUMPRODUCT(($H$7:$H$78=AE9)*($U$7:$U$78)*($F$7:$F$78))} -> 0 | AX9: =AV9-AW9 -> 0 | AY9: =AX9-MIN(AX8:AX11) -> 0 | AZ9: =AT9/AT12*1000+AU9/AU12*100+AY9/AY12*10+AV9/AV12 -> 0 | BA9: =AZ9/AZ12 -> 0 | BB9: {=SUMPRODUCT(($S$7:$S$78=AE9&"_win")*($X$7:$X$78))+SUMPRODUCT(($T$7:$T$78=AE9&"_win")*($X$7:$X$78))} -> 0 | BC9: {=SUMPRODUCT(($S$7:$S$78=AE9&"_draw")*($X$7:$X$78))+SUMPRODUCT(($T$7:$T$78=AE9&"_draw")*($X$7:$X$78))} -> 0 | BD9: {=SUMPRODUCT(($E$7:$E$78=AE9)*($X$7:$X$78)*($F$7:$F$78))+SUMPRODUCT(($H$7:$H$78=AE9)*($X$7:$X$78)*($G$7:$G$78))} -> 0 | BE9: {=SUMPRODUCT(($E$7:$E$78=AE9)*($X$7:$X$78)*($G$7:$G$78))+SUMPRODUCT(($H$7:$H$78=AE9)*($X$7:$X$78)*($F$7:$F$78))} -> 0 | BF9: =BD9-BE9 -> 0 | BG9: =BF9-MIN(BF8:BF11) -> 0 | BH9: =BB9/BB12*1000+BC9/BC12*100+BG9/BG12*10+BD9/BD12 -> 0 | BI9: =BH9/BH12 -> 0 | BK9: {=INDEX(T,24+MONTH(BP9),lang) & " " & DAY(BP9) & ", " & YEAR(BP9) & " " & (IF(HOUR(BP9)<10,0,"")&HOUR(BP9)) & ":" & (IF(MINUTE(BP9)<10,0,"")&MINUTE(BP9))} -> Jun 29, 2026 22:30 | BP9: =DATE(2026,6,29)+TIME(9,30,0)+gmt_delta -> 46202.938
A10: 4 | B10: {=INDEX(T,18+INT(MOD(R10-1,7)),lang)} -> Sat | C10: {=INDEX(T,24+MONTH(R10),lang) & " " & DAY(R10) & ", " & YEAR(R10)} -> Jun 13, 2026 | D10: =TIME(HOUR(R10),MINUTE(R10),0) -> 0.125 | E10: =AE26 -> United States | F10: 2 | G10: 1 | H10: =AE27 -> Paraguay | J10: =VLOOKUP(2,AD8:AN11,2,FALSE()) -> Korea Republic | K10: =L10+M10+N10 -> 3 | L10: =VLOOKUP(2,AD8:AN11,3,FALSE()) -> 2 | M10: =VLOOKUP(2,AD8:AN11,4,FALSE()) -> 0 | N10: =VLOOKUP(2,AD8:AN11,5,FALSE()) -> 1 | O10: =VLOOKUP(2,AD8:AN11,6,FALSE()) & " - " & VLOOKUP(2,AD8:AN11,7,FALSE()) -> 5 - 4 | P10: =L10*3+M10 -> 6 | R10: =DATE(2026,6,12)+TIME(14,0,0)+gmt_delta -> 46186.125 | S10: =IF(OR(F10="",G10=""),"",IF(F10>G10,E10&"_win",IF(F10<G10,E10&"_lose",E10&"_draw"))) -> United States_win | T10: =IF(S10="","",IF(F10<G10,H10&"_win",IF(F10>G10,H10&"_lose",H10&"_draw"))) -> Paraguay_lose | U10: =IF(S10="",0,IF(VLOOKUP(E10,$AE$8:$AN$77,10,FALSE())=VLOOKUP(H10,$AE$8:$AN$77,10,FALSE()),1,0)) -> 0 | V10: =U10*F10 -> 0 | W10: =U10*G10 -> 0 | X10: =IF(S10="",0,IF(VLOOKUP(E10,$AE$8:$AO$77,11,FALSE())=VLOOKUP(H10,$AE$8:$AO$77,11,FALSE()),1,0)) -> 0 | Y10: =X10*F10 -> 0 | Z10: =X10*G10 -> 0 | AA10: =IF(OR(E10=my_team,H10=my_team),1,IF(INT(MATCH(E10,$AE$8:$AE$78,0)/6)=$AA$6,1,0)) -> 0 | AB10: =IF(OR(F10="",G10=""),"",IF(F10>G10,1,IF(F10<G10,-1,0))) -> 1 | AD10: =COUNTIF(AR8:AR11,CONCATENATE(">=",AR10)) -> 2 | AE10: =VLOOKUP("Korea Republic",T,lang,FALSE()) -> Korea Republic | AF10: =COUNTIF($S$7:$T$78,"=" & AE10 & "_win") -> 2 | AG10: =COUNTIF($S$7:$T$78,"=" & AE10 & "_draw") -> 0 | AH10: =COUNTIF($S$7:$T$78,"=" & AE10 & "_lose") -> 1 | AI10: =SUMIF($E$7:$E$78,$AE10,$F$7:$F$78) + SUMIF($H$7:$H$78,$AE10,$G$7:$G$78) -> 5 | AJ10: =SUMIF($E$7:$E$78,$AE10,$G$7:$G$78) + SUMIF($H$7:$H$78,$AE10,$F$7:$F$78) -> 4 | AL10: =AI10-AJ10 -> 1 | AM10: =AL10-AL12 -> 5 | AN10: =AF10*3+AG10 -> 6 | AO10: =AN10/AN12*10+BA10 -> 6 | AP10: =AO10*10000000+BI10*100+AM10/AM12*10+AI10/AI12*1++IF(AQ10=0,ROW(),AQ10)/2000000 -> 60000006 | AQ10: =VLOOKUP(AE10,db_fifarank,2,FALSE()) -> 1588.66 | AR10: =AP10/AP12 -> 0.66666666 | AT10: {=SUMPRODUCT(($S$7:$S$78=AE10&"_win")*($U$7:$U$78))+SUMPRODUCT(($T$7:$T$78=AE10&"_win")*($U$7:$U$78))} -> 0 | AU10: {=SUMPRODUCT(($S$7:$S$78=AE10&"_draw")*($U$7:$U$78))+SUMPRODUCT(($T$7:$T$78=AE10&"_draw")*($U$7:$U$78))} -> 0 | AV10: {=SUMPRODUCT(($E$7:$E$78=AE10)*($U$7:$U$78)*($F$7:$F$78))+SUMPRODUCT(($H$7:$H$78=AE10)*($U$7:$U$78)*($G$7:$G$78))} -> 0 | AW10: {=SUMPRODUCT(($E$7:$E$78=AE10)*($U$7:$U$78)*($G$7:$G$78))+SUMPRODUCT(($H$7:$H$78=AE10)*($U$7:$U$78)*($F$7:$F$78))} -> 0 | AX10: =AV10-AW10 -> 0 | AY10: =AX10-MIN(AX8:AX11) -> 0 | AZ10: =AT10/AT12*1000+AU10/AU12*100+AY10/AY12*10+AV10/AV12 -> 0 | BA10: =AZ10/AZ12 -> 0 | BB10: {=SUMPRODUCT(($S$7:$S$78=AE10&"_win")*($X$7:$X$78))+SUMPRODUCT(($T$7:$T$78=AE10&"_win")*($X$7:$X$78))} -> 0 | BC10: {=SUMPRODUCT(($S$7:$S$78=AE10&"_draw")*($X$7:$X$78))+SUMPRODUCT(($T$7:$T$78=AE10&"_draw")*($X$7:$X$78))} -> 0 | BD10: {=SUMPRODUCT(($E$7:$E$78=AE10)*($X$7:$X$78)*($F$7:$F$78))+SUMPRODUCT(($H$7:$H$78=AE10)*($X$7:$X$78)*($G$7:$G$78))} -> 0 | BE10: {=SUMPRODUCT(($E$7:$E$78=AE10)*($X$7:$X$78)*($G$7:$G$78))+SUMPRODUCT(($H$7:$H$78=AE10)*($X$7:$X$78)*($F$7:$F$78))} -> 0 | BF10: =BD10-BE10 -> 0 | BG10: =BF10-MIN(BF8:BF11) -> 0 | BH10: =BB10/BB12*1000+BC10/BC12*100+BG10/BG12*10+BD10/BD12 -> 0 | BI10: =BH10/BH12 -> 0 | BK10: 74 | BL10: =AS32 -> Germany | BM10: 1 | BP10: =IF(OR(BM10="",BM11="",AND(BN10="",BN11<>""),AND(BN11="",BN10<>""),AND(BO10="",BO11<>""),AND(BO11="",BO10<>"")),"",BM10*1000+BN10*10+BO10) -> 1000
A11: 5 | B11: {=INDEX(T,18+INT(MOD(R11-1,7)),lang)} -> Sun | C11: {=INDEX(T,24+MONTH(R11),lang) & " " & DAY(R11) & ", " & YEAR(R11)} -> Jun 14, 2026 | D11: =TIME(HOUR(R11),MINUTE(R11),0) -> 0.125 | E11: =AE22 -> Haiti | F11: 0 | G11: 2 | H11: =AE23 -> Scotland | J11: =VLOOKUP(3,AD8:AN11,2,FALSE()) -> Czech Republic | K11: =L11+M11+N11 -> 3 | L11: =VLOOKUP(3,AD8:AN11,3,FALSE()) -> 1 | M11: =VLOOKUP(3,AD8:AN11,4,FALSE()) -> 0 | N11: =VLOOKUP(3,AD8:AN11,5,FALSE()) -> 2 | O11: =VLOOKUP(3,AD8:AN11,6,FALSE()) & " - " & VLOOKUP(3,AD8:AN11,7,FALSE()) -> 3 - 4 | P11: =L11*3+M11 -> 3 | R11: =DATE(2026,6,13)+TIME(14,0,0)+gmt_delta -> 46187.125 | S11: =IF(OR(F11="",G11=""),"",IF(F11>G11,E11&"_win",IF(F11<G11,E11&"_lose",E11&"_draw"))) -> Haiti_lose | T11: =IF(S11="","",IF(F11<G11,H11&"_win",IF(F11>G11,H11&"_lose",H11&"_draw"))) -> Scotland_win | U11: =IF(S11="",0,IF(VLOOKUP(E11,$AE$8:$AN$77,10,FALSE())=VLOOKUP(H11,$AE$8:$AN$77,10,FALSE()),1,0)) -> 0 | V11: =U11*F11 -> 0 | W11: =U11*G11 -> 0 | X11: =IF(S11="",0,IF(VLOOKUP(E11,$AE$8:$AO$77,11,FALSE())=VLOOKUP(H11,$AE$8:$AO$77,11,FALSE()),1,0)) -> 0 | Y11: =X11*F11 -> 0 | Z11: =X11*G11 -> 0 | AA11: =IF(OR(E11=my_team,H11=my_team),1,IF(INT(MATCH(E11,$AE$8:$AE$78,0)/6)=$AA$6,1,0)) -> 0 | AB11: =IF(OR(F11="",G11=""),"",IF(F11>G11,1,IF(F11<G11,-1,0))) -> -1 | AD11: =COUNTIF(AR8:AR11,CONCATENATE(">=",AR11)) -> 3 | AE11: =VLOOKUP("Czech Republic",T,lang,FALSE()) -> Czech Republic | AF11: =COUNTIF($S$7:$T$78,"=" & AE11 & "_win") -> 1 | AG11: =COUNTIF($S$7:$T$78,"=" & AE11 & "_draw") -> 0 | AH11: =COUNTIF($S$7:$T$78,"=" & AE11 & "_lose") -> 2 | AI11: =SUMIF($E$7:$E$78,$AE11,$F$7:$F$78) + SUMIF($H$7:$H$78,$AE11,$G$7:$G$78) -> 3 | AJ11: =SUMIF($E$7:$E$78,$AE11,$G$7:$G$78) + SUMIF($H$7:$H$78,$AE11,$F$7:$F$78) -> 4 | AL11: =AI11-AJ11 -> -1 | AM11: =AL11-AL12 -> 3 | AN11: =AF11*3+AG11 -> 3 | AO11: =AN11/AN12*10+BA11 -> 3 | AP11: =AO11*10000000+BI11*100+AM11/AM12*10+AI11/AI12*1++IF(AQ11=0,ROW(),AQ11)/2000000 -> 30000004 | AQ11: =VLOOKUP(AE11,db_fifarank,2,FALSE()) -> 1501.38 | AR11: =AP11/AP12 -> 0.33333334 | AT11: {=SUMPRODUCT(($S$7:$S$78=AE11&"_win")*($U$7:$U$78))+SUMPRODUCT(($T$7:$T$78=AE11&"_win")*($U$7:$U$78))} -> 0 | AU11: {=SUMPRODUCT(($S$7:$S$78=AE11&"_draw")*($U$7:$U$78))+SUMPRODUCT(($T$7:$T$78=AE11&"_draw")*($U$7:$U$78))} -> 0 | AV11: {=SUMPRODUCT(($E$7:$E$78=AE11)*($U$7:$U$78)*($F$7:$F$78))+SUMPRODUCT(($H$7:$H$78=AE11)*($U$7:$U$78)*($G$7:$G$78))} -> 0 | AW11: {=SUMPRODUCT(($E$7:$E$78=AE11)*($U$7:$U$78)*($G$7:$G$78))+SUMPRODUCT(($H$7:$H$78=AE11)*($U$7:$U$78)*($F$7:$F$78))} -> 0 | AX11: =AV11-AW11 -> 0 | AY11: =AX11-MIN(AX8:AX11) -> 0 | AZ11: =AT11/AT12*1000+AU11/AU12*100+AY11/AY12*10+AV11/AV12 -> 0 | BA11: =AZ11/AZ12 -> 0 | BB11: {=SUMPRODUCT(($S$7:$S$78=AE11&"_win")*($X$7:$X$78))+SUMPRODUCT(($T$7:$T$78=AE11&"_win")*($X$7:$X$78))} -> 0 | BC11: {=SUMPRODUCT(($S$7:$S$78=AE11&"_draw")*($X$7:$X$78))+SUMPRODUCT(($T$7:$T$78=AE11&"_draw")*($X$7:$X$78))} -> 0 | BD11: {=SUMPRODUCT(($E$7:$E$78=AE11)*($X$7:$X$78)*($F$7:$F$78))+SUMPRODUCT(($H$7:$H$78=AE11)*($X$7:$X$78)*($G$7:$G$78))} -> 0 | BE11: {=SUMPRODUCT(($E$7:$E$78=AE11)*($X$7:$X$78)*($G$7:$G$78))+SUMPRODUCT(($H$7:$H$78=AE11)*($X$7:$X$78)*($F$7:$F$78))} -> 0 | BF11: =BD11-BE11 -> 0 | BG11: =BF11-MIN(BF8:BF11) -> 0 | BH11: =BB11/BB12*1000+BC11/BC12*100+BG11/BG12*10+BD11/BD12 -> 0 | BI11: =BH11/BH12 -> 0 | BL11: =IF(group_round_completed,VLOOKUP('3rd places'!G3,AK80:AS91,9,FALSE()),"3rd Group A/B/C/D/F") -> Australia | BM11: 0 | BP11: =IF(BP10="","",BM11*1000+BN11*10+BO11) -> 0 | BR11: {=INDEX(T,24+MONTH(BW11),lang) & " " & DAY(BW11) & ", " & YEAR(BW11) & " " & (IF(HOUR(BW11)<10,0,"")&HOUR(BW11)) & ":" & (IF(MINUTE(BW11)<10,0,"")&MINUTE(BW11))} -> Jul 4, 2026 23:00 | BW11: =DATE(2026,7,4)+TIME(10,0,0)+gmt_delta -> 46207.958
A12: 6 | B12: {=INDEX(T,18+INT(MOD(R12-1,7)),lang)} -> Sun | C12: {=INDEX(T,24+MONTH(R12),lang) & " " & DAY(R12) & ", " & YEAR(R12)} -> Jun 14, 2026 | D12: =TIME(HOUR(R12),MINUTE(R12),0) -> 0.25 | E12: =AE28 -> Australia | F12: 0 | G12: 1 | H12: =AE29 -> Turkey | J12: =VLOOKUP(4,AD8:AN11,2,FALSE()) -> South Africa | K12: =L12+M12+N12 -> 3 | L12: =VLOOKUP(4,AD8:AN11,3,FALSE()) -> 0 | M12: =VLOOKUP(4,AD8:AN11,4,FALSE()) -> 0 | N12: =VLOOKUP(4,AD8:AN11,5,FALSE()) -> 3 | O12: =VLOOKUP(4,AD8:AN11,6,FALSE()) & " - " & VLOOKUP(4,AD8:AN11,7,FALSE()) -> 1 - 5 | P12: =L12*3+M12 -> 0 | R12: =DATE(2026,6,13)+TIME(17,0,0)+gmt_delta -> 46187.25 | S12: =IF(OR(F12="",G12=""),"",IF(F12>G12,E12&"_win",IF(F12<G12,E12&"_lose",E12&"_draw"))) -> Australia_lose | T12: =IF(S12="","",IF(F12<G12,H12&"_win",IF(F12>G12,H12&"_lose",H12&"_draw"))) -> Turkey_win | U12: =IF(S12="",0,IF(VLOOKUP(E12,$AE$8:$AN$77,10,FALSE())=VLOOKUP(H12,$AE$8:$AN$77,10,FALSE()),1,0)) -> 0 | V12: =U12*F12 -> 0 | W12: =U12*G12 -> 0 | X12: =IF(S12="",0,IF(VLOOKUP(E12,$AE$8:$AO$77,11,FALSE())=VLOOKUP(H12,$AE$8:$AO$77,11,FALSE()),1,0)) -> 0 | Y12: =X12*F12 -> 0 | Z12: =X12*G12 -> 0 | AA12: =IF(OR(E12=my_team,H12=my_team),1,IF(INT(MATCH(E12,$AE$8:$AE$78,0)/6)=$AA$6,1,0)) -> 0 | AB12: =IF(OR(F12="",G12=""),"",IF(F12>G12,1,IF(F12<G12,-1,0))) -> -1 | AF12: =MAX(AF8:AF11)-MIN(AF8:AF11)+1 -> 4 | AG12: =MAX(AG8:AG11)-MIN(AG8:AG11)+1 -> 1 | AH12: =MAX(AH8:AH11)-MIN(AH8:AH11)+1 -> 4 | AI12: =MAX(AI8:AI11)+1 -> 7 | AL12: =MIN(AL8:AL11) -> -4 | AM12: =MAX(AM8:AM11)+1 -> 9 | AN12: =MAX(AN8:AN11)+1 -> 10 | AO12: =MAX(AO8:AO11)+1 -> 10 | AP12: =MAX(AP8:AP11)+1 -> 90000011 | AT12: =MAX(AT8:AT11)-MIN(AT8:AT11)+1 -> 1 | AU12: =MAX(AU8:AU11)-MIN(AU8:AU11)+1 -> 1 | AV12: =MAX(AV8:AV11)-MIN(AV8:AV11)+1 -> 1 | AW12: =MAX(AW8:AW11)-MIN(AW8:AW11)+1 -> 1 | AY12: =MAX(AY8:AY11)-MIN(AY8:AY11)+1 -> 1 | AZ12: =MAX(AZ8:AZ11)+1 -> 1 | BB12: =MAX(BB8:BB11)-MIN(BB8:BB11)+1 -> 1 | BC12: =MAX(BC8:BC11)-MIN(BC8:BC11)+1 -> 1 | BD12: =MAX(BD8:BD11)-MIN(BD8:BD11)+1 -> 1 | BE12: =MAX(BE8:BE11)-MIN(BE8:BE11)+1 -> 1 | BG12: =MAX(BG8:BG11)-MIN(BG8:BG11)+1 -> 1 | BH12: =MAX(BH8:BH11)+1 -> 1 | BR12: 89 | BS12: =IF(BP10>BP11,BL10,IF(BP10<BP11,BL11,"")) -> Germany | BT12: 0 | BW12: =IF(OR(BT12="",BT13="",AND(BU12="",BU13<>""),AND(BU13="",BU12<>""),AND(BV12="",BV13<>""),AND(BV13="",BV12<>"")),"",BT12*1000+BU12*10+BV12) -> 0
A13: 7 | B13: {=INDEX(T,18+INT(MOD(R13-1,7)),lang)} -> Sun | C13: {=INDEX(T,24+MONTH(R13),lang) & " " & DAY(R13) & ", " & YEAR(R13)} -> Jun 14, 2026 | D13: =TIME(HOUR(R13),MINUTE(R13),0) -> 0 | E13: =AE20 -> Brazil | F13: 1 | G13: 0 | H13: =AE21 -> Morocco | R13: =DATE(2026,6,13)+TIME(11,0,0)+gmt_delta -> 46187 | S13: =IF(OR(F13="",G13=""),"",IF(F13>G13,E13&"_win",IF(F13<G13,E13&"_lose",E13&"_draw"))) -> Brazil_win | T13: =IF(S13="","",IF(F13<G13,H13&"_win",IF(F13>G13,H13&"_lose",H13&"_draw"))) -> Morocco_lose | U13: =IF(S13="",0,IF(VLOOKUP(E13,$AE$8:$AN$77,10,FALSE())=VLOOKUP(H13,$AE$8:$AN$77,10,FALSE()),1,0)) -> 0 | V13: =U13*F13 -> 0 | W13: =U13*G13 -> 0 | X13: =IF(S13="",0,IF(VLOOKUP(E13,$AE$8:$AO$77,11,FALSE())=VLOOKUP(H13,$AE$8:$AO$77,11,FALSE()),1,0)) -> 0 | Y13: =X13*F13 -> 0 | Z13: =X13*G13 -> 0 | AA13: =IF(OR(E13=my_team,H13=my_team),1,IF(INT(MATCH(E13,$AE$8:$AE$78,0)/6)=$AA$6,1,0)) -> 0 | AB13: =IF(OR(F13="",G13=""),"",IF(F13>G13,1,IF(F13<G13,-1,0))) -> 1 | BK13: {=INDEX(T,24+MONTH(BP13),lang) & " " & DAY(BP13) & ", " & YEAR(BP13) & " " & (IF(HOUR(BP13)<10,0,"")&HOUR(BP13)) & ":" & (IF(MINUTE(BP13)<10,0,"")&MINUTE(BP13))} -> Jun 30, 2026 23:00 | BP13: =DATE(2026,6,30)+TIME(10,0,0)+gmt_delta -> 46203.958 | BS13: =IF(BP14>BP15,BL14,IF(BP14<BP15,BL15,"")) -> France | BT13: 1 | BW13: =IF(BW12="","",BT13*1000+BU13*10+BV13) -> 1000
A14: 8 | B14: {=INDEX(T,18+INT(MOD(R14-1,7)),lang)} -> Sat | C14: {=INDEX(T,24+MONTH(R14),lang) & " " & DAY(R14) & ", " & YEAR(R14)} -> Jun 13, 2026 | D14: =TIME(HOUR(R14),MINUTE(R14),0) -> 0.875 | E14: =AE16 -> Qatar | F14: 1 | G14: 2 | H14: =AE17 -> Switzerland | J14: {=INDEX(T,9,lang) & " " & "B"} -> Group B | K14: {=INDEX(T,10,lang)} -> PL | L14: {=INDEX(T,11,lang)} -> W | M14: {=INDEX(T,12,lang)} -> DRAW | N14: {=INDEX(T,13,lang)} -> L | O14: {=INDEX(T,14,lang)} -> GF - GA | P14: {=INDEX(T,15,lang)} -> PNT | R14: =DATE(2026,6,13)+TIME(8,0,0)+gmt_delta -> 46186.875 | S14: =IF(OR(F14="",G14=""),"",IF(F14>G14,E14&"_win",IF(F14<G14,E14&"_lose",E14&"_draw"))) -> Qatar_lose | T14: =IF(S14="","",IF(F14<G14,H14&"_win",IF(F14>G14,H14&"_lose",H14&"_draw"))) -> Switzerland_win | U14: =IF(S14="",0,IF(VLOOKUP(E14,$AE$8:$AN$77,10,FALSE())=VLOOKUP(H14,$AE$8:$AN$77,10,FALSE()),1,0)) -> 0 | V14: =U14*F14 -> 0 | W14: =U14*G14 -> 0 | X14: =IF(S14="",0,IF(VLOOKUP(E14,$AE$8:$AO$77,11,FALSE())=VLOOKUP(H14,$AE$8:$AO$77,11,FALSE()),1,0)) -> 0 | Y14: =X14*F14 -> 0 | Z14: =X14*G14 -> 0 | AA14: =IF(OR(E14=my_team,H14=my_team),1,IF(INT(MATCH(E14,$AE$8:$AE$78,0)/6)=$AA$6,1,0)) -> 0 | AB14: =IF(OR(F14="",G14=""),"",IF(F14>G14,1,IF(F14<G14,-1,0))) -> -1 | AD14: =COUNTIF(AR14:AR17,CONCATENATE(">=",AR14)) -> 2 | AE14: =VLOOKUP("Canada",T,lang,FALSE()) -> Canada | AF14: =COUNTIF($S$7:$T$78,"=" & AE14 & "_win") -> 2 | AG14: =COUNTIF($S$7:$T$78,"=" & AE14 & "_draw") -> 0 | AH14: =COUNTIF($S$7:$T$78,"=" & AE14 & "_lose") -> 1 | AI14: =SUMIF($E$7:$E$78,$AE14,$F$7:$F$78) + SUMIF($H$7:$H$78,$AE14,$G$7:$G$78) -> 5 | AJ14: =SUMIF($E$7:$E$78,$AE14,$G$7:$G$78) + SUMIF($H$7:$H$78,$AE14,$F$7:$F$78) -> 4 | AL14: =AI14-AJ14 -> 1 | AM14: =AL14-AL18 -> 5 | AN14: =AF14*3+AG14 -> 6 | AO14: =AN14/AN18*10+BA14 -> 6 | AP14: =AO14*10000000+BI14*100+AM14/AM18*10+AI14/AI18*1++IF(AQ14=0,ROW(),AQ14)/2000000 -> 60000006 | AQ14: =VLOOKUP(AE14,db_fifarank,2,FALSE()) -> 1556.48 | AR14: =AP14/AP18 -> 0.66666666 | AS14: =IF(SUM(AF14:AH17)=12,J15,"1B") -> Switzerland | AT14: {=SUMPRODUCT(($S$7:$S$78=AE14&"_win")*($U$7:$U$78))+SUMPRODUCT(($T$7:$T$78=AE14&"_win")*($U$7:$U$78))} -> 0 | AU14: {=SUMPRODUCT(($S$7:$S$78=AE14&"_draw")*($U$7:$U$78))+SUMPRODUCT(($T$7:$T$78=AE14&"_draw")*($U$7:$U$78))} -> 0 | AV14: {=SUMPRODUCT(($E$7:$E$78=AE14)*($U$7:$U$78)*($F$7:$F$78))+SUMPRODUCT(($H$7:$H$78=AE14)*($U$7:$U$78)*($G$7:$G$78))} -> 0 | AW14: {=SUMPRODUCT(($E$7:$E$78=AE14)*($U$7:$U$78)*($G$7:$G$78))+SUMPRODUCT(($H$7:$H$78=AE14)*($U$7:$U$78)*($F$7:$F$78))} -> 0 | AX14: =AV14-AW14 -> 0 | AY14: =AX14-MIN(AX14:AX17) -> 0 | AZ14: =AT14/AT18*1000+AU14/AU18*100+AY14/AY18*10+AV14/AV18 -> 0 | BA14: =AZ14/AZ18 -> 0 | BB14: {=SUMPRODUCT(($S$7:$S$78=AE14&"_win")*($X$7:$X$78))+SUMPRODUCT(($T$7:$T$78=AE14&"_win")*($X$7:$X$78))} -> 0 | BC14: {=SUMPRODUCT(($S$7:$S$78=AE14&"_draw")*($X$7:$X$78))+SUMPRODUCT(($T$7:$T$78=AE14&"_draw")*($X$7:$X$78))} -> 0 | BD14: {=SUMPRODUCT(($E$7:$E$78=AE14)*($X$7:$X$78)*($F$7:$F$78))+SUMPRODUCT(($H$7:$H$78=AE14)*($X$7:$X$78)*($G$7:$G$78))} -> 0 | BE14: {=SUMPRODUCT(($E$7:$E$78=AE14)*($X$7:$X$78)*($G$7:$G$78))+SUMPRODUCT(($H$7:$H$78=AE14)*($X$7:$X$78)*($F$7:$F$78))} -> 0 | BF14: =BD14-BE14 -> 0 | BG14: =BF14-MIN(BF14:BF17) -> 0 | BH14: =BB14/BB18*1000+BC14/BC18*100+BG14/BG18*10+BD14/BD18 -> 0 | BI14: =BH14/BH18 -> 0 | BK14: 77 | BL14: =AS56 -> France | BM14: 1 | BP14: =IF(OR(BM14="",BM15="",AND(BN14="",BN15<>""),AND(BN15="",BN14<>""),AND(BO14="",BO15<>""),AND(BO15="",BO14<>"")),"",BM14*1000+BN14*10+BO14) -> 1000
A15: 9 | B15: {=INDEX(T,18+INT(MOD(R15-1,7)),lang)} -> Mon | C15: {=INDEX(T,24+MONTH(R15),lang) & " " & DAY(R15) & ", " & YEAR(R15)} -> Jun 15, 2026 | D15: =TIME(HOUR(R15),MINUTE(R15),0) -> 0.041666667 | E15: =AE34 -> Ivory Coast | F15: 0 | G15: 1 | H15: =AE35 -> Ecuador | J15: =VLOOKUP(1,AD14:AN17,2,FALSE()) -> Switzerland | K15: =L15+M15+N15 -> 3 | L15: =VLOOKUP(1,AD14:AN17,3,FALSE()) -> 3 | M15: =VLOOKUP(1,AD14:AN17,4,FALSE()) -> 0 | N15: =VLOOKUP(1,AD14:AN17,5,FALSE()) -> 0 | O15: =VLOOKUP(1,AD14:AN17,6,FALSE()) & " - " & VLOOKUP(1,AD14:AN17,7,FALSE()) -> 6 - 2 | P15: =L15*3+M15 -> 9 | R15: =DATE(2026,6,14)+TIME(12,0,0)+gmt_delta -> 46188.042 | S15: =IF(OR(F15="",G15=""),"",IF(F15>G15,E15&"_win",IF(F15<G15,E15&"_lose",E15&"_draw"))) -> Ivory Coast_lose | T15: =IF(S15="","",IF(F15<G15,H15&"_win",IF(F15>G15,H15&"_lose",H15&"_draw"))) -> Ecuador_win | U15: =IF(S15="",0,IF(VLOOKUP(E15,$AE$8:$AN$77,10,FALSE())=VLOOKUP(H15,$AE$8:$AN$77,10,FALSE()),1,0)) -> 0 | V15: =U15*F15 -> 0 | W15: =U15*G15 -> 0 | X15: =IF(S15="",0,IF(VLOOKUP(E15,$AE$8:$AO$77,11,FALSE())=VLOOKUP(H15,$AE$8:$AO$77,11,FALSE()),1,0)) -> 0 | Y15: =X15*F15 -> 0 | Z15: =X15*G15 -> 0 | AA15: =IF(OR(E15=my_team,H15=my_team),1,IF(INT(MATCH(E15,$AE$8:$AE$78,0)/6)=$AA$6,1,0)) -> 0 | AB15: =IF(OR(F15="",G15=""),"",IF(F15>G15,1,IF(F15<G15,-1,0))) -> -1 | AD15: =COUNTIF(AR14:AR17,CONCATENATE(">=",AR15)) -> 4 | AE15: =VLOOKUP("Bosnia and Herzegovina",T,lang,FALSE()) -> Bosnia and Herzegovina | AF15: =COUNTIF($S$7:$T$78,"=" & AE15 & "_win") -> 0 | AG15: =COUNTIF($S$7:$T$78,"=" & AE15 & "_draw") -> 0 | AH15: =COUNTIF($S$7:$T$78,"=" & AE15 & "_lose") -> 3 | AI15: =SUMIF($E$7:$E$78,$AE15,$F$7:$F$78) + SUMIF($H$7:$H$78,$AE15,$G$7:$G$78) -> 1 | AJ15: =SUMIF($E$7:$E$78,$AE15,$G$7:$G$78) + SUMIF($H$7:$H$78,$AE15,$F$7:$F$78) -> 5 | AL15: =AI15-AJ15 -> -4 | AM15: =AL15-AL18 -> 0 | AN15: =AF15*3+AG15 -> 0 | AO15: =AN15/AN18*10+BA15 -> 0 | AP15: =AO15*10000000+BI15*100+AM15/AM18*10+AI15/AI18*1++IF(AQ15=0,ROW(),AQ15)/2000000 -> 0.14355006 | AQ15: =VLOOKUP(AE15,db_fifarank,2,FALSE()) -> 1385.84 | AR15: =AP15/AP18 -> 1.5950005e-09 | AS15: =IF(SUM(AF14:AH17)=12,J16,"2B") -> Canada | AT15: {=SUMPRODUCT(($S$7:$S$78=AE15&"_win")*($U$7:$U$78))+SUMPRODUCT(($T$7:$T$78=AE15&"_win")*($U$7:$U$78))} -> 0 | AU15: {=SUMPRODUCT(($S$7:$S$78=AE15&"_draw")*($U$7:$U$78))+SUMPRODUCT(($T$7:$T$78=AE15&"_draw")*($U$7:$U$78))} -> 0 | AV15: {=SUMPRODUCT(($E$7:$E$78=AE15)*($U$7:$U$78)*($F$7:$F$78))+SUMPRODUCT(($H$7:$H$78=AE15)*($U$7:$U$78)*($G$7:$G$78))} -> 0 | AW15: {=SUMPRODUCT(($E$7:$E$78=AE15)*($U$7:$U$78)*($G$7:$G$78))+SUMPRODUCT(($H$7:$H$78=AE15)*($U$7:$U$78)*($F$7:$F$78))} -> 0 | AX15: =AV15-AW15 -> 0 | AY15: =AX15-MIN(AX14:AX17) -> 0 | AZ15: =AT15/AT18*1000+AU15/AU18*100+AY15/AY18*10+AV15/AV18 -> 0 | BA15: =AZ15/AZ18 -> 0 | BB15: {=SUMPRODUCT(($S$7:$S$78=AE15&"_win")*($X$7:$X$78))+SUMPRODUCT(($T$7:$T$78=AE15&"_win")*($X$7:$X$78))} -> 0 | BC15: {=SUMPRODUCT(($S$7:$S$78=AE15&"_draw")*($X$7:$X$78))+SUMPRODUCT(($T$7:$T$78=AE15&"_draw")*($X$7:$X$78))} -> 0 | BD15: {=SUMPRODUCT(($E$7:$E$78=AE15)*($X$7:$X$78)*($F$7:$F$78))+SUMPRODUCT(($H$7:$H$78=AE15)*($X$7:$X$78)*($G$7:$G$78))} -> 0 | BE15: {=SUMPRODUCT(($E$7:$E$78=AE15)*($X$7:$X$78)*($G$7:$G$78))+SUMPRODUCT(($H$7:$H$78=AE15)*($X$7:$X$78)*($F$7:$F$78))} -> 0 | BF15: =BD15-BE15 -> 0 | BG15: =BF15-MIN(BF14:BF17) -> 0 | BH15: =BB15/BB18*1000+BC15/BC18*100+BG15/BG18*10+BD15/BD18 -> 0 | BI15: =BH15/BH18 -> 0 | BL15: =IF(group_round_completed,VLOOKUP('3rd places'!I3,AK80:AS91,9,FALSE()),"3rd Group C/D/F/G/H") -> Egypt | BM15: 0 | BP15: =IF(BP14="","",BM15*1000+BN15*10+BO15) -> 0 | BY15: {=INDEX(T,24+MONTH(CD15),lang) & " " & DAY(CD15) & ", " & YEAR(CD15) & " " & (IF(HOUR(CD15)<10,0,"")&HOUR(CD15)) & ":" & (IF(MINUTE(CD15)<10,0,"")&MINUTE(CD15))} -> Jul 9, 2026 22:00 | CD15: =DATE(2026,7,9)+TIME(9,0,0)+gmt_delta -> 46212.917
A16: 10 | B16: {=INDEX(T,18+INT(MOD(R16-1,7)),lang)} -> Sun | C16: {=INDEX(T,24+MONTH(R16),lang) & " " & DAY(R16) & ", " & YEAR(R16)} -> Jun 14, 2026 | D16: =TIME(HOUR(R16),MINUTE(R16),0) -> 0.79166667 | E16: =AE32 -> Germany | F16: 2 | G16: 0 | H16: =AE33 -> Curaçao | J16: =VLOOKUP(2,AD14:AN17,2,FALSE()) -> Canada | K16: =L16+M16+N16 -> 3 | L16: =VLOOKUP(2,AD14:AN17,3,FALSE()) -> 2 | M16: =VLOOKUP(2,AD14:AN17,4,FALSE()) -> 0 | N16: =VLOOKUP(2,AD14:AN17,5,FALSE()) -> 1 | O16: =VLOOKUP(2,AD14:AN17,6,FALSE()) & " - " & VLOOKUP(2,AD14:AN17,7,FALSE()) -> 5 - 4 | P16: =L16*3+M16 -> 6 | R16: =DATE(2026,6,14)+TIME(6,0,0)+gmt_delta -> 46187.792 | S16: =IF(OR(F16="",G16=""),"",IF(F16>G16,E16&"_win",IF(F16<G16,E16&"_lose",E16&"_draw"))) -> Germany_win | T16: =IF(S16="","",IF(F16<G16,H16&"_win",IF(F16>G16,H16&"_lose",H16&"_draw"))) -> Curaçao_lose | U16: =IF(S16="",0,IF(VLOOKUP(E16,$AE$8:$AN$77,10,FALSE())=VLOOKUP(H16,$AE$8:$AN$77,10,FALSE()),1,0)) -> 0 | V16: =U16*F16 -> 0 | W16: =U16*G16 -> 0 | X16: =IF(S16="",0,IF(VLOOKUP(E16,$AE$8:$AO$77,11,FALSE())=VLOOKUP(H16,$AE$8:$AO$77,11,FALSE()),1,0)) -> 0 | Y16: =X16*F16 -> 0 | Z16: =X16*G16 -> 0 | AA16: =IF(OR(E16=my_team,H16=my_team),1,IF(INT(MATCH(E16,$AE$8:$AE$78,0)/6)=$AA$6,1,0)) -> 0 | AB16: =IF(OR(F16="",G16=""),"",IF(F16>G16,1,IF(F16<G16,-1,0))) -> 1 | AD16: =COUNTIF(AR14:AR17,CONCATENATE(">=",AR16)) -> 3 | AE16: =VLOOKUP("Qatar",T,lang,FALSE()) -> Qatar | AF16: =COUNTIF($S$7:$T$78,"=" & AE16 & "_win") -> 1 | AG16: =COUNTIF($S$7:$T$78,"=" & AE16 & "_draw") -> 0 | AH16: =COUNTIF($S$7:$T$78,"=" & AE16 & "_lose") -> 2 | AI16: =SUMIF($E$7:$E$78,$AE16,$F$7:$F$78) + SUMIF($H$7:$H$78,$AE16,$G$7:$G$78) -> 3 | AJ16: =SUMIF($E$7:$E$78,$AE16,$G$7:$G$78) + SUMIF($H$7:$H$78,$AE16,$F$7:$F$78) -> 4 | AL16: =AI16-AJ16 -> -1 | AM16: =AL16-AL18 -> 3 | AN16: =AF16*3+AG16 -> 3 | AO16: =AN16/AN18*10+BA16 -> 3 | AP16: =AO16*10000000+BI16*100+AM16/AM18*10+AI16/AI18*1++IF(AQ16=0,ROW(),AQ16)/2000000 -> 30000004 | AQ16: =VLOOKUP(AE16,db_fifarank,2,FALSE()) -> 1454.96 | AR16: =AP16/AP18 -> 0.33333334 | AT16: {=SUMPRODUCT(($S$7:$S$78=AE16&"_win")*($U$7:$U$78))+SUMPRODUCT(($T$7:$T$78=AE16&"_win")*($U$7:$U$78))} -> 0 | AU16: {=SUMPRODUCT(($S$7:$S$78=AE16&"_draw")*($U$7:$U$78))+SUMPRODUCT(($T$7:$T$78=AE16&"_draw")*($U$7:$U$78))} -> 0 | AV16: {=SUMPRODUCT(($E$7:$E$78=AE16)*($U$7:$U$78)*($F$7:$F$78))+SUMPRODUCT(($H$7:$H$78=AE16)*($U$7:$U$78)*($G$7:$G$78))} -> 0 | AW16: {=SUMPRODUCT(($E$7:$E$78=AE16)*($U$7:$U$78)*($G$7:$G$78))+SUMPRODUCT(($H$7:$H$78=AE16)*($U$7:$U$78)*($F$7:$F$78))} -> 0 | AX16: =AV16-AW16 -> 0 | AY16: =AX16-MIN(AX14:AX17) -> 0 | AZ16: =AT16/AT18*1000+AU16/AU18*100+AY16/AY18*10+AV16/AV18 -> 0 | BA16: =AZ16/AZ18 -> 0 | BB16: {=SUMPRODUCT(($S$7:$S$78=AE16&"_win")*($X$7:$X$78))+SUMPRODUCT(($T$7:$T$78=AE16&"_win")*($X$7:$X$78))} -> 0 | BC16: {=SUMPRODUCT(($S$7:$S$78=AE16&"_draw")*($X$7:$X$78))+SUMPRODUCT(($T$7:$T$78=AE16&"_draw")*($X$7:$X$78))} -> 0 | BD16: {=SUMPRODUCT(($E$7:$E$78=AE16)*($X$7:$X$78)*($F$7:$F$78))+SUMPRODUCT(($H$7:$H$78=AE16)*($X$7:$X$78)*($G$7:$G$78))} -> 0 | BE16: {=SUMPRODUCT(($E$7:$E$78=AE16)*($X$7:$X$78)*($G$7:$G$78))+SUMPRODUCT(($H$7:$H$78=AE16)*($X$7:$X$78)*($F$7:$F$78))} -> 0 | BF16: =BD16-BE16 -> 0 | BG16: =BF16-MIN(BF14:BF17) -> 0 | BH16: =BB16/BB18*1000+BC16/BC18*100+BG16/BG18*10+BD16/BD18 -> 0 | BI16: =BH16/BH18 -> 0 | BY16: 97 | BZ16: =IF(BW12>BW13,BS12,IF(BW12<BW13,BS13,"")) -> France | CA16: 1 | CD16: =IF(OR(CA16="",CA17="",AND(CB16="",CB17<>""),AND(CB17="",CB16<>""),AND(CC16="",CC17<>""),AND(CC17="",CC16<>"")),"",CA16*1000+CB16*10+CC16) -> 1000
A17: 11 | B17: {=INDEX(T,18+INT(MOD(R17-1,7)),lang)} -> Sun | C17: {=INDEX(T,24+MONTH(R17),lang) & " " & DAY(R17) & ", " & YEAR(R17)} -> Jun 14, 2026 | D17: =TIME(HOUR(R17),MINUTE(R17),0) -> 0.91666667 | E17: =AE38 -> Netherlands | F17: 2 | G17: 1 | H17: =AE39 -> Japan | J17: =VLOOKUP(3,AD14:AN17,2,FALSE()) -> Qatar | K17: =L17+M17+N17 -> 3 | L17: =VLOOKUP(3,AD14:AN17,3,FALSE()) -> 1 | M17: =VLOOKUP(3,AD14:AN17,4,FALSE()) -> 0 | N17: =VLOOKUP(3,AD14:AN17,5,FALSE()) -> 2 | O17: =VLOOKUP(3,AD14:AN17,6,FALSE()) & " - " & VLOOKUP(3,AD14:AN17,7,FALSE()) -> 3 - 4 | P17: =L17*3+M17 -> 3 | R17: =DATE(2026,6,14)+TIME(9,0,0)+gmt_delta -> 46187.917 | S17: =IF(OR(F17="",G17=""),"",IF(F17>G17,E17&"_win",IF(F17<G17,E17&"_lose",E17&"_draw"))) -> Netherlands_win | T17: =IF(S17="","",IF(F17<G17,H17&"_win",IF(F17>G17,H17&"_lose",H17&"_draw"))) -> Japan_lose | U17: =IF(S17="",0,IF(VLOOKUP(E17,$AE$8:$AN$77,10,FALSE())=VLOOKUP(H17,$AE$8:$AN$77,10,FALSE()),1,0)) -> 0 | V17: =U17*F17 -> 0 | W17: =U17*G17 -> 0 | X17: =IF(S17="",0,IF(VLOOKUP(E17,$AE$8:$AO$77,11,FALSE())=VLOOKUP(H17,$AE$8:$AO$77,11,FALSE()),1,0)) -> 0 | Y17: =X17*F17 -> 0 | Z17: =X17*G17 -> 0 | AA17: =IF(OR(E17=my_team,H17=my_team),1,IF(INT(MATCH(E17,$AE$8:$AE$78,0)/6)=$AA$6,1,0)) -> 0 | AB17: =IF(OR(F17="",G17=""),"",IF(F17>G17,1,IF(F17<G17,-1,0))) -> 1 | AD17: =COUNTIF(AR14:AR17,CONCATENATE(">=",AR17)) -> 1 | AE17: =VLOOKUP("Switzerland",T,lang,FALSE()) -> Switzerland | AF17: =COUNTIF($S$7:$T$78,"=" & AE17 & "_win") -> 3 | AG17: =COUNTIF($S$7:$T$78,"=" & AE17 & "_draw") -> 0 | AH17: =COUNTIF($S$7:$T$78,"=" & AE17 & "_lose") -> 0 | AI17: =SUMIF($E$7:$E$78,$AE17,$F$7:$F$78) + SUMIF($H$7:$H$78,$AE17,$G$7:$G$78) -> 6 | AJ17: =SUMIF($E$7:$E$78,$AE17,$G$7:$G$78) + SUMIF($H$7:$H$78,$AE17,$F$7:$F$78) -> 2 | AL17: =AI17-AJ17 -> 4 | AM17: =AL17-AL18 -> 8 | AN17: =AF17*3+AG17 -> 9 | AO17: =AN17/AN18*10+BA17 -> 9 | AP17: =AO17*10000000+BI17*100+AM17/AM18*10+AI17/AI18*1++IF(AQ17=0,ROW(),AQ17)/2000000 -> 90000010 | AQ17: =VLOOKUP(AE17,db_fifarank,2,FALSE()) -> 1649.4 | AR17: =AP17/AP18 -> 0.99999999 | AT17: {=SUMPRODUCT(($S$7:$S$78=AE17&"_win")*($U$7:$U$78))+SUMPRODUCT(($T$7:$T$78=AE17&"_win")*($U$7:$U$78))} -> 0 | AU17: {=SUMPRODUCT(($S$7:$S$78=AE17&"_draw")*($U$7:$U$78))+SUMPRODUCT(($T$7:$T$78=AE17&"_draw")*($U$7:$U$78))} -> 0 | AV17: {=SUMPRODUCT(($E$7:$E$78=AE17)*($U$7:$U$78)*($F$7:$F$78))+SUMPRODUCT(($H$7:$H$78=AE17)*($U$7:$U$78)*($G$7:$G$78))} -> 0 | AW17: {=SUMPRODUCT(($E$7:$E$78=AE17)*($U$7:$U$78)*($G$7:$G$78))+SUMPRODUCT(($H$7:$H$78=AE17)*($U$7:$U$78)*($F$7:$F$78))} -> 0 | AX17: =AV17-AW17 -> 0 | AY17: =AX17-MIN(AX14:AX17) -> 0 | AZ17: =AT17/AT18*1000+AU17/AU18*100+AY17/AY18*10+AV17/AV18 -> 0 | BA17: =AZ17/AZ18 -> 0 | BB17: {=SUMPRODUCT(($S$7:$S$78=AE17&"_win")*($X$7:$X$78))+SUMPRODUCT(($T$7:$T$78=AE17&"_win")*($X$7:$X$78))} -> 0 | BC17: {=SUMPRODUCT(($S$7:$S$78=AE17&"_draw")*($X$7:$X$78))+SUMPRODUCT(($T$7:$T$78=AE17&"_draw")*($X$7:$X$78))} -> 0 | BD17: {=SUMPRODUCT(($E$7:$E$78=AE17)*($X$7:$X$78)*($F$7:$F$78))+SUMPRODUCT(($H$7:$H$78=AE17)*($X$7:$X$78)*($G$7:$G$78))} -> 0 | BE17: {=SUMPRODUCT(($E$7:$E$78=AE17)*($X$7:$X$78)*($G$7:$G$78))+SUMPRODUCT(($H$7:$H$78=AE17)*($X$7:$X$78)*($F$7:$F$78))} -> 0 | BF17: =BD17-BE17 -> 0 | BG17: =BF17-MIN(BF14:BF17) -> 0 | BH17: =BB17/BB18*1000+BC17/BC18*100+BG17/BG18*10+BD17/BD18 -> 0 | BI17: =BH17/BH18 -> 0 | BK17: {=INDEX(T,24+MONTH(BP17),lang) & " " & DAY(BP17) & ", " & YEAR(BP17) & " " & (IF(HOUR(BP17)<10,0,"")&HOUR(BP17)) & ":" & (IF(MINUTE(BP17)<10,0,"")&MINUTE(BP17))} -> Jun 28, 2026 21:00 | BP17: =DATE(2026,6,28)+TIME(8,0,0)+gmt_delta -> 46201.875 | BZ17: =IF(BW20>BW21,BS20,IF(BW20<BW21,BS21,"")) -> Netherlands | CA17: 0 | CD17: =IF(CD16="","",CA17*1000+CB17*10+CC17) -> 0
A18: 12 | B18: {=INDEX(T,18+INT(MOD(R18-1,7)),lang)} -> Mon | C18: {=INDEX(T,24+MONTH(R18),lang) & " " & DAY(R18) & ", " & YEAR(R18)} -> Jun 15, 2026 | D18: =TIME(HOUR(R18),MINUTE(R18),0) -> 0.16666667 | E18: =AE40 -> Sweden | F18: 1 | G18: 0 | H18: =AE41 -> Tunisia | J18: =VLOOKUP(4,AD14:AN17,2,FALSE()) -> Bosnia and Herzegovina | K18: =L18+M18+N18 -> 3 | L18: =VLOOKUP(4,AD14:AN17,3,FALSE()) -> 0 | M18: =VLOOKUP(4,AD14:AN17,4,FALSE()) -> 0 | N18: =VLOOKUP(4,AD14:AN17,5,FALSE()) -> 3 | O18: =VLOOKUP(4,AD14:AN17,6,FALSE()) & " - " & VLOOKUP(4,AD14:AN17,7,FALSE()) -> 1 - 5 | P18: =L18*3+M18 -> 0 | R18: =DATE(2026,6,14)+TIME(15,0,0)+gmt_delta -> 46188.167 | S18: =IF(OR(F18="",G18=""),"",IF(F18>G18,E18&"_win",IF(F18<G18,E18&"_lose",E18&"_draw"))) -> Sweden_win | T18: =IF(S18="","",IF(F18<G18,H18&"_win",IF(F18>G18,H18&"_lose",H18&"_draw"))) -> Tunisia_lose | U18: =IF(S18="",0,IF(VLOOKUP(E18,$AE$8:$AN$77,10,FALSE())=VLOOKUP(H18,$AE$8:$AN$77,10,FALSE()),1,0)) -> 0 | V18: =U18*F18 -> 0 | W18: =U18*G18 -> 0 | X18: =IF(S18="",0,IF(VLOOKUP(E18,$AE$8:$AO$77,11,FALSE())=VLOOKUP(H18,$AE$8:$AO$77,11,FALSE()),1,0)) -> 0 | Y18: =X18*F18 -> 0 | Z18: =X18*G18 -> 0 | AA18: =IF(OR(E18=my_team,H18=my_team),1,IF(INT(MATCH(E18,$AE$8:$AE$78,0)/6)=$AA$6,1,0)) -> 0 | AB18: =IF(OR(F18="",G18=""),"",IF(F18>G18,1,IF(F18<G18,-1,0))) -> 1 | AF18: =MAX(AF14:AF17)-MIN(AF14:AF17)+1 -> 4 | AG18: =MAX(AG14:AG17)-MIN(AG14:AG17)+1 -> 1 | AH18: =MAX(AH14:AH17)-MIN(AH14:AH17)+1 -> 4 | AI18: =MAX(AI14:AI17)+1 -> 7 | AL18: =MIN(AL14:AL17) -> -4 | AM18: =MAX(AM14:AM17)+1 -> 9 | AN18: =MAX(AN14:AN17)+1 -> 10 | AO18: =MAX(AO14:AO17)+1 -> 10 | AP18: =MAX(AP14:AP17)+1 -> 90000011 | AT18: =MAX(AT14:AT17)-MIN(AT14:AT17)+1 -> 1 | AU18: =MAX(AU14:AU17)-MIN(AU14:AU17)+1 -> 1 | AV18: =MAX(AV14:AV17)-MIN(AV14:AV17)+1 -> 1 | AW18: =MAX(AW14:AW17)-MIN(AW14:AW17)+1 -> 1 | AY18: =MAX(AY14:AY17)-MIN(AY14:AY17)+1 -> 1 | AZ18: =MAX(AZ14:AZ17)+1 -> 1 | BB18: =MAX(BB14:BB17)-MIN(BB14:BB17)+1 -> 1 | BC18: =MAX(BC14:BC17)-MIN(BC14:BC17)+1 -> 1 | BD18: =MAX(BD14:BD17)-MIN(BD14:BD17)+1 -> 1 | BE18: =MAX(BE14:BE17)-MIN(BE14:BE17)+1 -> 1 | BG18: =MAX(BG14:BG17)-MIN(BG14:BG17)+1 -> 1 | BH18: =MAX(BH14:BH17)+1 -> 1 | BK18: 73 | BL18: =AS9 -> Korea Republic | BM18: 1 | BP18: =IF(OR(BM18="",BM19="",AND(BN18="",BN19<>""),AND(BN19="",BN18<>""),AND(BO18="",BO19<>""),AND(BO19="",BO18<>"")),"",BM18*1000+BN18*10+BO18) -> 1000
A19: 13 | B19: {=INDEX(T,18+INT(MOD(R19-1,7)),lang)} -> Tue | C19: {=INDEX(T,24+MONTH(R19),lang) & " " & DAY(R19) & ", " & YEAR(R19)} -> Jun 16, 2026 | D19: =TIME(HOUR(R19),MINUTE(R19),0) -> 0 | E19: =AE52 -> Saudi Arabia | F19: 0 | G19: 2 | H19: =AE53 -> Uruguay | R19: =DATE(2026,6,15)+TIME(11,0,0)+gmt_delta -> 46189 | S19: =IF(OR(F19="",G19=""),"",IF(F19>G19,E19&"_win",IF(F19<G19,E19&"_lose",E19&"_draw"))) -> Saudi Arabia_lose | T19: =IF(S19="","",IF(F19<G19,H19&"_win",IF(F19>G19,H19&"_lose",H19&"_draw"))) -> Uruguay_win | U19: =IF(S19="",0,IF(VLOOKUP(E19,$AE$8:$AN$77,10,FALSE())=VLOOKUP(H19,$AE$8:$AN$77,10,FALSE()),1,0)) -> 0 | V19: =U19*F19 -> 0 | W19: =U19*G19 -> 0 | X19: =IF(S19="",0,IF(VLOOKUP(E19,$AE$8:$AO$77,11,FALSE())=VLOOKUP(H19,$AE$8:$AO$77,11,FALSE()),1,0)) -> 0 | Y19: =X19*F19 -> 0 | Z19: =X19*G19 -> 0 | AA19: =IF(OR(E19=my_team,H19=my_team),1,IF(INT(MATCH(E19,$AE$8:$AE$78,0)/6)=$AA$6,1,0)) -> 0 | AB19: =IF(OR(F19="",G19=""),"",IF(F19>G19,1,IF(F19<G19,-1,0))) -> -1 | BL19: =AS15 -> Canada | BM19: 0 | BP19: =IF(BP18="","",BM19*1000+BN19*10+BO19) -> 0 | BR19: {=INDEX(T,24+MONTH(BW19),lang) & " " & DAY(BW19) & ", " & YEAR(BW19) & " " & (IF(HOUR(BW19)<10,0,"")&HOUR(BW19)) & ":" & (IF(MINUTE(BW19)<10,0,"")&MINUTE(BW19))} -> Jul 4, 2026 19:00 | BW19: =DATE(2026,7,4)+TIME(6,0,0)+gmt_delta -> 46207.792
A20: 14 | B20: {=INDEX(T,18+INT(MOD(R20-1,7)),lang)} -> Mon | C20: {=INDEX(T,24+MONTH(R20),lang) & " " & DAY(R20) & ", " & YEAR(R20)} -> Jun 15, 2026 | D20: =TIME(HOUR(R20),MINUTE(R20),0) -> 0.75 | E20: =AE50 -> Spain | F20: 2 | G20: 0 | H20: =AE51 -> Cape Verde | J20: {=INDEX(T,9,lang) & " " & "C"} -> Group C | K20: {=INDEX(T,10,lang)} -> PL | L20: {=INDEX(T,11,lang)} -> W | M20: {=INDEX(T,12,lang)} -> DRAW | N20: {=INDEX(T,13,lang)} -> L | O20: {=INDEX(T,14,lang)} -> GF - GA | P20: {=INDEX(T,15,lang)} -> PNT | R20: =DATE(2026,6,15)+TIME(5,0,0)+gmt_delta -> 46188.75 | S20: =IF(OR(F20="",G20=""),"",IF(F20>G20,E20&"_win",IF(F20<G20,E20&"_lose",E20&"_draw"))) -> Spain_win | T20: =IF(S20="","",IF(F20<G20,H20&"_win",IF(F20>G20,H20&"_lose",H20&"_draw"))) -> Cape Verde_lose | U20: =IF(S20="",0,IF(VLOOKUP(E20,$AE$8:$AN$77,10,FALSE())=VLOOKUP(H20,$AE$8:$AN$77,10,FALSE()),1,0)) -> 0 | V20: =U20*F20 -> 0 | W20: =U20*G20 -> 0 | X20: =IF(S20="",0,IF(VLOOKUP(E20,$AE$8:$AO$77,11,FALSE())=VLOOKUP(H20,$AE$8:$AO$77,11,FALSE()),1,0)) -> 0 | Y20: =X20*F20 -> 0 | Z20: =X20*G20 -> 0 | AA20: =IF(OR(E20=my_team,H20=my_team),1,IF(INT(MATCH(E20,$AE$8:$AE$78,0)/6)=$AA$6,1,0)) -> 0 | AB20: =IF(OR(F20="",G20=""),"",IF(F20>G20,1,IF(F20<G20,-1,0))) -> 1 | AD20: =COUNTIF(AR20:AR23,CONCATENATE(">=",AR20)) -> 1 | AE20: =VLOOKUP("Brazil",T,lang,FALSE()) -> Brazil | AF20: =COUNTIF($S$7:$T$78,"=" & AE20 & "_win") -> 3 | AG20: =COUNTIF($S$7:$T$78,"=" & AE20 & "_draw") -> 0 | AH20: =COUNTIF($S$7:$T$78,"=" & AE20 & "_lose") -> 0 | AI20: =SUMIF($E$7:$E$78,$AE20,$F$7:$F$78) + SUMIF($H$7:$H$78,$AE20,$G$7:$G$78) -> 5 | AJ20: =SUMIF($E$7:$E$78,$AE20,$G$7:$G$78) + SUMIF($H$7:$H$78,$AE20,$F$7:$F$78) -> 0 | AL20: =AI20-AJ20 -> 5 | AM20: =AL20-AL24 -> 11 | AN20: =AF20*3+AG20 -> 9 | AO20: =AN20/AN24*10+BA20 -> 9 | AP20: =AO20*10000000+BI20*100+AM20/AM24*10+AI20/AI24*1++IF(AQ20=0,ROW(),AQ20)/2000000 -> 90000010 | AQ20: =VLOOKUP(AE20,db_fifarank,2,FALSE()) -> 1761.16 | AR20: =AP20/AP24 -> 0.99999999 | AS20: =IF(SUM(AF20:AH23)=12,J21,"1C") -> Brazil | AT20: {=SUMPRODUCT(($S$7:$S$78=AE20&"_win")*($U$7:$U$78))+SUMPRODUCT(($T$7:$T$78=AE20&"_win")*($U$7:$U$78))} -> 0 | AU20: {=SUMPRODUCT(($S$7:$S$78=AE20&"_draw")*($U$7:$U$78))+SUMPRODUCT(($T$7:$T$78=AE20&"_draw")*($U$7:$U$78))} -> 0 | AV20: {=SUMPRODUCT(($E$7:$E$78=AE20)*($U$7:$U$78)*($F$7:$F$78))+SUMPRODUCT(($H$7:$H$78=AE20)*($U$7:$U$78)*($G$7:$G$78))} -> 0 | AW20: {=SUMPRODUCT(($E$7:$E$78=AE20)*($U$7:$U$78)*($G$7:$G$78))+SUMPRODUCT(($H$7:$H$78=AE20)*($U$7:$U$78)*($F$7:$F$78))} -> 0 | AX20: =AV20-AW20 -> 0 | AY20: =AX20-MIN(AX20:AX23) -> 0 | AZ20: =AT20/AT24*1000+AU20/AU24*100+AY20/AY24*10+AV20/AV24 -> 0 | BA20: =AZ20/AZ24 -> 0 | BB20: {=SUMPRODUCT(($S$7:$S$78=AE20&"_win")*($X$7:$X$78))+SUMPRODUCT(($T$7:$T$78=AE20&"_win")*($X$7:$X$78))} -> 0 | BC20: {=SUMPRODUCT(($S$7:$S$78=AE20&"_draw")*($X$7:$X$78))+SUMPRODUCT(($T$7:$T$78=AE20&"_draw")*($X$7:$X$78))} -> 0 | BD20: {=SUMPRODUCT(($E$7:$E$78=AE20)*($X$7:$X$78)*($F$7:$F$78))+SUMPRODUCT(($H$7:$H$78=AE20)*($X$7:$X$78)*($G$7:$G$78))} -> 0 | BE20: {=SUMPRODUCT(($E$7:$E$78=AE20)*($X$7:$X$78)*($G$7:$G$78))+SUMPRODUCT(($H$7:$H$78=AE20)*($X$7:$X$78)*($F$7:$F$78))} -> 0 | BF20: =BD20-BE20 -> 0 | BG20: =BF20-MIN(BF20:BF23) -> 0 | BH20: =BB20/BB24*1000+BC20/BC24*100+BG20/BG24*10+BD20/BD24 -> 0 | BI20: =BH20/BH24 -> 0 | BR20: 90 | BS20: =IF(BP18>BP19,BL18,IF(BP18<BP19,BL19,"")) -> Korea Republic | BT20: 0 | BW20: =IF(OR(BT20="",BT21="",AND(BU20="",BU21<>""),AND(BU21="",BU20<>""),AND(BV20="",BV21<>""),AND(BV21="",BV20<>"")),"",BT20*1000+BU20*10+BV20) -> 0
A21: 15 | B21: {=INDEX(T,18+INT(MOD(R21-1,7)),lang)} -> Tue | C21: {=INDEX(T,24+MONTH(R21),lang) & " " & DAY(R21) & ", " & YEAR(R21)} -> Jun 16, 2026 | D21: =TIME(HOUR(R21),MINUTE(R21),0) -> 0.125 | E21: =AE46 -> Iran | F21: 2 | G21: 0 | H21: =AE47 -> New Zealand | J21: =VLOOKUP(1,AD20:AN23,2,FALSE()) -> Brazil | K21: =L21+M21+N21 -> 3 | L21: =VLOOKUP(1,AD20:AN23,3,FALSE()) -> 3 | M21: =VLOOKUP(1,AD20:AN23,4,FALSE()) -> 0 | N21: =VLOOKUP(1,AD20:AN23,5,FALSE()) -> 0 | O21: =VLOOKUP(1,AD20:AN23,6,FALSE()) & " - " & VLOOKUP(1,AD20:AN23,7,FALSE()) -> 5 - 0 | P21: =L21*3+M21 -> 9 | R21: =DATE(2026,6,15)+TIME(14,0,0)+gmt_delta -> 46189.125 | S21: =IF(OR(F21="",G21=""),"",IF(F21>G21,E21&"_win",IF(F21<G21,E21&"_lose",E21&"_draw"))) -> Iran_win | T21: =IF(S21="","",IF(F21<G21,H21&"_win",IF(F21>G21,H21&"_lose",H21&"_draw"))) -> New Zealand_lose | U21: =IF(S21="",0,IF(VLOOKUP(E21,$AE$8:$AN$77,10,FALSE())=VLOOKUP(H21,$AE$8:$AN$77,10,FALSE()),1,0)) -> 0 | V21: =U21*F21 -> 0 | W21: =U21*G21 -> 0 | X21: =IF(S21="",0,IF(VLOOKUP(E21,$AE$8:$AO$77,11,FALSE())=VLOOKUP(H21,$AE$8:$AO$77,11,FALSE()),1,0)) -> 0 | Y21: =X21*F21 -> 0 | Z21: =X21*G21 -> 0 | AA21: =IF(OR(E21=my_team,H21=my_team),1,IF(INT(MATCH(E21,$AE$8:$AE$78,0)/6)=$AA$6,1,0)) -> 0 | AB21: =IF(OR(F21="",G21=""),"",IF(F21>G21,1,IF(F21<G21,-1,0))) -> 1 | AD21: =COUNTIF(AR20:AR23,CONCATENATE(">=",AR21)) -> 2 | AE21: =VLOOKUP("Morocco",T,lang,FALSE()) -> Morocco | AF21: =COUNTIF($S$7:$T$78,"=" & AE21 & "_win") -> 2 | AG21: =COUNTIF($S$7:$T$78,"=" & AE21 & "_draw") -> 0 | AH21: =COUNTIF($S$7:$T$78,"=" & AE21 & "_lose") -> 1 | AI21: =SUMIF($E$7:$E$78,$AE21,$F$7:$F$78) + SUMIF($H$7:$H$78,$AE21,$G$7:$G$78) -> 4 | AJ21: =SUMIF($E$7:$E$78,$AE21,$G$7:$G$78) + SUMIF($H$7:$H$78,$AE21,$F$7:$F$78) -> 1 | AL21: =AI21-AJ21 -> 3 | AM21: =AL21-AL24 -> 9 | AN21: =AF21*3+AG21 -> 6 | AO21: =AN21/AN24*10+BA21 -> 6 | AP21: =AO21*10000000+BI21*100+AM21/AM24*10+AI21/AI24*1++IF(AQ21=0,ROW(),AQ21)/2000000 -> 60000008 | AQ21: =VLOOKUP(AE21,db_fifarank,2,FALSE()) -> 1755.87 | AR21: =AP21/AP24 -> 0.66666668 | AS21: =IF(SUM(AF20:AH23)=12,J22,"2C") -> Morocco | AT21: {=SUMPRODUCT(($S$7:$S$78=AE21&"_win")*($U$7:$U$78))+SUMPRODUCT(($T$7:$T$78=AE21&"_win")*($U$7:$U$78))} -> 0 | AU21: {=SUMPRODUCT(($S$7:$S$78=AE21&"_draw")*($U$7:$U$78))+SUMPRODUCT(($T$7:$T$78=AE21&"_draw")*($U$7:$U$78))} -> 0 | AV21: {=SUMPRODUCT(($E$7:$E$78=AE21)*($U$7:$U$78)*($F$7:$F$78))+SUMPRODUCT(($H$7:$H$78=AE21)*($U$7:$U$78)*($G$7:$G$78))} -> 0 | AW21: {=SUMPRODUCT(($E$7:$E$78=AE21)*($U$7:$U$78)*($G$7:$G$78))+SUMPRODUCT(($H$7:$H$78=AE21)*($U$7:$U$78)*($F$7:$F$78))} -> 0 | AX21: =AV21-AW21 -> 0 | AY21: =AX21-MIN(AX20:AX23) -> 0 | AZ21: =AT21/AT24*1000+AU21/AU24*100+AY21/AY24*10+AV21/AV24 -> 0 | BA21: =AZ21/AZ24 -> 0 | BB21: {=SUMPRODUCT(($S$7:$S$78=AE21&"_win")*($X$7:$X$78))+SUMPRODUCT(($T$7:$T$78=AE21&"_win")*($X$7:$X$78))} -> 0 | BC21: {=SUMPRODUCT(($S$7:$S$78=AE21&"_draw")*($X$7:$X$78))+SUMPRODUCT(($T$7:$T$78=AE21&"_draw")*($X$7:$X$78))} -> 0 | BD21: {=SUMPRODUCT(($E$7:$E$78=AE21)*($X$7:$X$78)*($F$7:$F$78))+SUMPRODUCT(($H$7:$H$78=AE21)*($X$7:$X$78)*($G$7:$G$78))} -> 0 | BE21: {=SUMPRODUCT(($E$7:$E$78=AE21)*($X$7:$X$78)*($G$7:$G$78))+SUMPRODUCT(($H$7:$H$78=AE21)*($X$7:$X$78)*($F$7:$F$78))} -> 0 | BF21: =BD21-BE21 -> 0 | BG21: =BF21-MIN(BF20:BF23) -> 0 | BH21: =BB21/BB24*1000+BC21/BC24*100+BG21/BG24*10+BD21/BD24 -> 0 | BI21: =BH21/BH24 -> 0 | BK21: {=INDEX(T,24+MONTH(BP21),lang) & " " & DAY(BP21) & ", " & YEAR(BP21) & " " & (IF(HOUR(BP21)<10,0,"")&HOUR(BP21)) & ":" & (IF(MINUTE(BP21)<10,0,"")&MINUTE(BP21))} -> Jun 30, 2026 03:00 | BP21: =DATE(2026,6,29)+TIME(14,0,0)+gmt_delta -> 46203.125 | BS21: =IF(BP22>BP23,BL22,IF(BP22<BP23,BL23,"")) -> Netherlands | BT21: 1 | BW21: =IF(BW20="","",BT21*1000+BU21*10+BV21) -> 1000
